Workbook
Name Tháng: #REF!
Name Tháng: #REF!
Name Tháng: #REF!

Sheet foxz

Sheet BẢNG KÊ CHI TIẾT XE MẪU 
A1: CÔNG TY TNHH THƯƠNG MẠI DỊCH VỤ VẬN TẢI SUMO | P1: Cộng Hòa Xã Hội Chủ Nghĩa Việt Nam
A2: ĐC: Khu Lãm Làng, Phường Vân Dương, Thành phố Bắc Ninh, Tỉnh Bắc Ninh | P2: Độc Lập - Tự Do - Hạnh Phúc
A3: BẢNG ĐỐI CHIẾU KHỐI LƯỢNG VÀ GIÁ TRỊ SỬ DỤNG XE Ô TÔ 租车使用对账明细表
A4: Tháng 12 năm 2020 2020年12月
A5: Loại xe: 07 chỗ ngồi- BKS: 99A-289.12
A6: Khách hàng客户: CÔNG TY TNHH CÔNG NGHIỆP NIENYI VIỆT NAM
V7: ĐVT: VND
A8: NGÀY 日期 | B8: Km đầu 开始公里 | C8: Km cuối 结束公里 | D8: SỐ KM 使用公里数 | E8: SỐ KM TRỌN GÓI THEO HỢP ĐỒNG 按合同的公里数 | G8: KM PHỤ TRỘI NGÀY THƯỜNG 平日超过公里数 | J8: Giờ B.Đầu 开始时间 | K8: Giờ K.Thúc 结束时间 | N8: GIỜ PHỤ TRỘI NGÀY THƯỜNG 平日超过时间 | Q8: ĐƠN GIÁ NGÀY QUA ĐÊM 过夜单价 | R8: ĐƠN GIÁ NGÀY CN/LỄ 礼拜天或节日的单价 | T8: GIỜ PHỤ TRỘI NGÀY CHỦ NHẬT/LỄ 礼拜天或节日超过时间 | W8: TIỀN ĂN 餐费 | Y8: TIỀN VÉ XE 过路费、车票 | Z8: CỘNG 合计
E9: SỐ KM 公里数 | F9: GIÁ TRỊ 金额 | G9: SỐ KM PHỤ TRỘI 超过公里数 | H9: ĐƠN GIÁ 单价 | I9: THÀNH TIỀN 金额 | N9: GIỜ 工时 | O9: ĐƠN GIÁ 单价 | P9: THÀNH TIÊN 金额 | R9: KM 公里 | S9: SỐ TIỀN 金额 | T9: GIỜ 工时 | U9: ĐƠN GIÁ 单价 | V9: THÀNH TIỀN 金额 | W9: SỐ BỮA ĂN 餐数量 | X9: THÀNH TIỀN 金额
E10: 3000 | F10: 22000000 | G10: 0 | H10: 5000 | I10: =G10*H10 -> 0 | Q10: 0 | U10: 0 | V10: =T10*U10 -> 0 | Z10: =F10+I10+P10+Q10+S10+V10+X10+Y10 -> 22000000
A11: 44166 | B11: 81098 | C11: 81117 | D11: =C11-B11 -> 19 | J11: 0.30555556 | K11: 0.85416667 | L11: =IF(("7:00"-J11)<=0,0,("7:00"-J11)) -> 0 | M11: =IF((K11-"18:00")<=0,0,(K11-"18:00")) -> 0.10416667 | N11: 1 | O11: 100000 | P11: =N11*O11 -> 100000 | X11: =W11*50000 -> 0 | Z11: =SUM(I11+P11+Q11+S11+V11+X11+Y11) -> 100000
A12: 44167 | B12: 81117 | C12: 81146 | D12: =C12-B12 -> 29 | J12: 0.30555556 | K12: 0.85416667 | L12: =IF(("7:00"-J12)<=0,0,("7:00"-J12)) -> 0 | M12: =IF((K12-"18:00")<=0,0,(K12-"18:00")) -> 0.10416667 | N12: 1 | O12: 100000 | P12: =N12*O12 -> 100000 | X12: =W12*50000 -> 0 | Z12: =SUM(I12+P12+Q12+S12+V12+X12+Y12) -> 100000
A13: 44168 | B13: 81146 | C13: 81164 | D13: =C13-B13 -> 18 | J13: 0.30555556 | K13: 0.85416667 | L13: =IF(("7:00"-J13)<=0,0,("7:00"-J13)) -> 0 | M13: =IF((K13-"18:00")<=0,0,(K13-"18:00")) -> 0.10416667 | N13: 1 | O13: 100000 | P13: =N13*O13 -> 100000 | X13: =W13*50000 -> 0 | Z13: =SUM(I13+P13+Q13+S13+V13+X13+Y13) -> 100000
A14: 44169 | B14: 81164 | C14: 81192 | D14: =C14-B14 -> 28 | J14: 0.3125 | K14: 0.85416667 | L14: =IF(("7:00"-J14)<=0,0,("7:00"-J14)) -> 0 | M14: =IF((K14-"18:00")<=0,0,(K14-"18:00")) -> 0.10416667 | N14: 1 | O14: 100000 | P14: =N14*O14 -> 100000 | X14: =W14*50000 -> 0 | Z14: =SUM(I14+P14+Q14+S14+V14+X14+Y14) -> 100000
A15: 44170 | B15: 81192 | C15: 81263 | D15: =C15-B15 -> 71 | J15: 0.3125 | K15: 0.95833333 | L15: =IF(("7:00"-J15)<=0,0,("7:00"-J15)) -> 0 | M15: =IF((K15-"18:00")<=0,0,(K15-"18:00")) -> 0.20833333 | N15: 1 | O15: 140000 | P15: =N15*O15 -> 140000 | X15: =W15*50000 -> 0 | Z15: =SUM(I15+P15+Q15+S15+V15+X15+Y15) -> 140000
A16: 44171 | B16: 0 | C16: 0 | D16: =C16-B16 -> 0 | J16: 0.3125 | K16: 0.77083333 | L16: =IF(("7:00"-J16)<=0,0,("7:00"-J16)) -> 0 | M16: =IF((K16-"18:00")<=0,0,(K16-"18:00")) -> 0.020833333 | N16: 0 | O16: 100000 | P16: =N16*O16 -> 0 | X16: =W16*50000 -> 0 | Z16: =SUM(I16+P16+Q16+S16+V16+X16+Y16) -> 0
A17: 44172 | B17: 81286 | C17: 81304 | D17: =C17-B17 -> 18 | J17: 0.3125 | K17: 0.85416667 | L17: =IF(("7:00"-J17)<=0,0,("7:00"-J17)) -> 0 | M17: =IF((K17-"18:00")<=0,0,(K17-"18:00")) -> 0.10416667 | N17: 1 | O17: 100000 | P17: =N17*O17 -> 100000 | X17: =W17*50000 -> 0 | Z17: =SUM(I17+P17+Q17+S17+V17+X17+Y17) -> 100000
A18: 44173 | B18: 81304 | C18: 81355 | D18: =C18-B18 -> 51 | J18: 0.3125 | K18: 0.85416667 | L18: =IF(("7:00"-J18)<=0,0,("7:00"-J18)) -> 0 | M18: =IF((K18-"18:00")<=0,0,(K18-"18:00")) -> 0.10416667 | N18: 1 | O18: 100000 | P18: =N18*O18 -> 100000 | X18: =W18*50000 -> 0 | Z18: =SUM(I18+P18+Q18+S18+V18+X18+Y18) -> 100000
A19: 44174 | B19: 81355 | C19: 81760 | D19: =C19-B19 -> 405 | J19: 0.3125 | K19: 0.91666667 | L19: =IF(("7:00"-J19)<=0,0,("7:00"-J19)) -> 0 | M19: =IF((K19-"18:00")<=0,0,(K19-"18:00")) -> 0.16666667 | N19: 1 | O19: 100000 | P19: =N19*O19 -> 100000 | W19: 1 | X19: =W19*50000 -> 50000 | Y19: 270000 | Z19: =SUM(I19+P19+Q19+S19+V19+X19+Y19) -> 420000
A20: 44175 | B20: 81760 | C20: 81780 | D20: =C20-B20 -> 20 | J20: 0.3125 | K20: 0.875 | L20: =IF(("7:00"-J20)<=0,0,("7:00"-J20)) -> 0 | M20: =IF((K20-"18:00")<=0,0,(K20-"18:00")) -> 0.125 | N20: 1 | O20: 100000 | P20: =N20*O20 -> 100000 | X20: =W20*50000 -> 0 | Z20: =SUM(I20+P20+Q20+S20+V20+X20+Y20) -> 100000
A21: 44176 | B21: 81780 | C21: 81868 | D21: =C21-B21 -> 88 | J21: 0.3125 | K21: 0.85416667 | L21: =IF(("7:00"-J21)<=0,0,("7:00"-J21)) -> 0 | M21: =IF((K21-"18:00")<=0,0,(K21-"18:00")) -> 0.10416667 | N21: 1 | O21: 100000 | P21: =N21*O21 -> 100000 | X21: =W21*50000 -> 0 | Z21: =SUM(I21+P21+Q21+S21+V21+X21+Y21) -> 100000
A22: 44177 | B22: 81868 | C22: 82056 | D22: =C22-B22 -> 188 | J22: 0.3125 | K22: 0.77083333 | L22: =IF(("7:00"-J22)<=0,0,("7:00"-J22)) -> 0 | M22: =IF((K22-"18:00")<=0,0,(K22-"18:00")) -> 0.020833333 | N22: 0 | O22: 100000 | P22: =N22*O22 -> 0 | X22: =W22*50000 -> 0 | Z22: =SUM(I22+P22+Q22+S22+V22+X22+Y22) -> 0
A23: 44178 | B23: 0 | C23: 0 | D23: =C23-B23 -> 0 | J23: 0.3125 | K23: 0.77083333 | L23: =IF(("7:00"-J23)<=0,0,("7:00"-J23)) -> 0 | M23: =IF((K23-"18:00")<=0,0,(K23-"18:00")) -> 0.020833333 | N23: 0 | O23: 100000 | P23: =N23*O23 -> 0 | X23: =W23*50000 -> 0 | Z23: =SUM(I23+P23+Q23+S23+V23+X23+Y23) -> 0
A24: 44179 | B24: 82056 | C24: 82077 | D24: =C24-B24 -> 21 | J24: 0.3125 | K24: 0.77083333 | L24: =IF(("7:00"-J24)<=0,0,("7:00"-J24)) -> 0 | M24: =IF((K24-"18:00")<=0,0,(K24-"18:00")) -> 0.020833333 | O24: 100000 | P24: =N24*O24 -> 0 | X24: =W24*50000 -> 0 | Z24: =SUM(I24+P24+Q24+S24+V24+X24+Y24) -> 0
A25: 44180 | B25: 82077 | C25: 82139 | D25: =C25-B25 -> 62 | J25: 0.3125 | K25: 0.85416667 | L25: =IF(("7:00"-J25)<=0,0,("7:00"-J25)) -> 0 | M25: =IF((K25-"18:00")<=0,0,(K25-"18:00")) -> 0.10416667 | N25: 1 | O25: 100000 | P25: =N25*O25 -> 100000 | X25: =W25*50000 -> 0 | Z25: =SUM(I25+P25+Q25+S25+V25+X25+Y25) -> 100000
A26: 44181 | B26: 82139 | C26: 82180 | D26: =C26-B26 -> 41 | J26: 0.3125 | K26: 0.85416667 | L26: =IF(("7:00"-J26)<=0,0,("7:00"-J26)) -> 0 | M26: =IF((K26-"18:00")<=0,0,(K26-"18:00")) -> 0.10416667 | N26: 1 | O26: 100000 | P26: =N26*O26 -> 100000 | X26: =W26*50000 -> 0 | Z26: =SUM(I26+P26+Q26+S26+V26+X26+Y26) -> 100000
A27: 44182 | B27: 82180 | C27: 82201 | D27: =C27-B27 -> 21 | J27: 0.3125 | K27: 0.77083333 | L27: =IF(("7:00"-J27)<=0,0,("7:00"-J27)) -> 0 | M27: =IF((K27-"18:00")<=0,0,(K27-"18:00")) -> 0.020833333 | O27: 100000 | P27: =N27*O27 -> 0 | X27: =W27*50000 -> 0 | Z27: =SUM(I27+P27+Q27+S27+V27+X27+Y27) -> 0
A28: 44183 | B28: 82201 | C28: 82299 | D28: =C28-B28 -> 98 | J28: 0.3125 | K28: 0.77083333 | L28: =IF(("7:00"-J28)<=0,0,("7:00"-J28)) -> 0 | M28: =IF((K28-"18:00")<=0,0,(K28-"18:00")) -> 0.020833333 | O28: 100000 | P28: =N28*O28 -> 0 | X28: =W28*50000 -> 0 | Z28: =SUM(I28+P28+Q28+S28+V28+X28+Y28) -> 0
A29: 44184 | B29: 82299 | C29: 82392 | D29: =C29-B29 -> 93 | J29: 0.3125 | K29: 0.91666667 | L29: =IF(("7:00"-J29)<=0,0,("7:00"-J29)) -> 0 | M29: =IF((K29-"18:00")<=0,0,(K29-"18:00")) -> 0.16666667 | N29: 1 | O29: 100000 | P29: =N29*O29 -> 100000 | W29: 1 | X29: =W29*50000 -> 50000 | Z29: =SUM(I29+P29+Q29+S29+V29+X29+Y29) -> 150000
A30: 44185 | B30: 0 | C30: 0 | D30: =C30-B30 -> 0 | J30: 0.3125 | K30: 0.77083333 | L30: =IF(("7:00"-J30)<=0,0,("7:00"-J30)) -> 0 | M30: =IF((K30-"18:00")<=0,0,(K30-"18:00")) -> 0.020833333 | N30: 0 | O30: 100000 | P30: =N30*O30 -> 0 | X30: =W30*50000 -> 0 | Z30: =SUM(I30+P30+Q30+S30+V30+X30+Y30) -> 0
A31: 44186 | B31: 82462 | C31: 82494 | D31: =C31-B31 -> 32 | J31: 0.3125 | K31: 0.85416667 | L31: =IF(("7:00"-J31)<=0,0,("7:00"-J31)) -> 0 | M31: =IF((K31-"18:00")<=0,0,(K31-"18:00")) -> 0.10416667 | N31: 1 | O31: 100000 | P31: =N31*O31 -> 100000 | X31: =W31*50000 -> 0 | Z31: =SUM(I31+P31+Q31+S31+V31+X31+Y31) -> 100000
A32: 44187 | B32: 82494 | C32: 82515 | D32: =C32-B32 -> 21 | J32: 0.3125 | K32: 0.85416667 | L32: =IF(("7:00"-J32)<=0,0,("7:00"-J32)) -> 0 | M32: =IF((K32-"18:00")<=0,0,(K32-"18:00")) -> 0.10416667 | N32: 1 | O32: 100000 | P32: =N32*O32 -> 100000 | X32: =W32*50000 -> 0 | Z32: =SUM(I32+P32+Q32+S32+V32+X32+Y32) -> 100000
A33: 44188 | B33: 82515 | C33: 82606 | D33: =C33-B33 -> 91 | J33: 0.3125 | K33: 0.85416667 | L33: =IF(("7:00"-J33)<=0,0,("7:00"-J33)) -> 0 | M33: =IF((K33-"18:00")<=0,0,(K33-"18:00")) -> 0.10416667 | N33: 1 | O33: 100000 | P33: =N33*O33 -> 100000 | X33: =W33*50000 -> 0 | Z33: =SUM(I33+P33+Q33+S33+V33+X33+Y33) -> 100000
A34: 44189 | B34: 82606 | C34: 82989 | D34: =C34-B34 -> 383 | J34: 0.3125 | K34: 0.85416667 | L34: =IF(("7:00"-J34)<=0,0,("7:00"-J34)) -> 0 | M34: =IF((K34-"18:00")<=0,0,(K34-"18:00")) -> 0.10416667 | N34: 1 | O34: 100000 | P34: =N34*O34 -> 100000 | W34: 1 | X34: =W34*50000 -> 50000 | Y34: 270000 | Z34: =SUM(I34+P34+Q34+S34+V34+X34+Y34) -> 420000
A35: 44190 | B35: 82989 | C35: 83212 | D35: =C35-B35 -> 223 | J35: 0.3125 | K35: 0.52083333 | L35: =IF(("7:00"-J35)<=0,0,("7:00"-J35)) -> 0 | M35: =IF((K35-"18:00")<=0,0,(K35-"18:00")) -> 0 | N35: 2 | O35: 100000 | P35: =N35*O35 -> 200000 | W35: 1 | X35: =W35*50000 -> 50000 | Z35: =SUM(I35+P35+Q35+S35+V35+X35+Y35) -> 250000
A36: 44191 | B36: 83212 | C36: 83609 | D36: =C36-B36 -> 397 | J36: 0.3125 | K36: 0.85416667 | L36: =IF(("7:00"-J36)<=0,0,("7:00"-J36)) -> 0 | M36: =IF((K36-"18:00")<=0,0,(K36-"18:00")) -> 0.10416667 | N36: 1 | O36: 100000 | P36: =N36*O36 -> 100000 | W36: 1 | X36: =W36*50000 -> 50000 | Y36: 370000 | Z36: =SUM(I36+P36+Q36+S36+V36+X36+Y36) -> 520000
A37: 44192 | B37: 0 | C37: 0 | D37: =C37-B37 -> 0 | J37: 0.3125 | K37: 0.77083333 | L37: =IF(("7:00"-J37)<=0,0,("7:00"-J37)) -> 0 | M37: =IF((K37-"18:00")<=0,0,(K37-"18:00")) -> 0.020833333 | O37: 100000 | P37: =N37*O37 -> 0 | X37: =W37*50000 -> 0 | Z37: =SUM(I37+P37+Q37+S37+V37+X37+Y37) -> 0
A38: 44193 | B38: 83805 | C38: 83895 | D38: =C38-B38 -> 90 | J38: 0.3125 | K38: 0.85416667 | L38: =IF(("7:00"-J38)<=0,0,("7:00"-J38)) -> 0 | M38: =IF((K38-"18:00")<=0,0,(K38-"18:00")) -> 0.10416667 | N38: 1 | O38: 100000 | P38: =N38*O38 -> 100000 | X38: =W38*50000 -> 0 | Z38: =SUM(I38+P38+Q38+S38+V38+X38+Y38) -> 100000
A39: 44194 | B39: 83895 | C39: 83951 | D39: =C39-B39 -> 56 | J39: 0.3125 | K39: 0.77083333 | L39: =IF(("7:00"-J39)<=0,0,("7:00"-J39)) -> 0 | M39: =IF((K39-"18:00")<=0,0,(K39-"18:00")) -> 0.020833333 | O39: 100000 | P39: =N39*O39 -> 0 | X39: =W39*50000 -> 0 | Z39: =SUM(I39+P39+Q39+S39+V39+X39+Y39) -> 0
A40: 44195 | B40: 83951 | C40: 84079 | D40: =C40-B40 -> 128 | J40: 0.3125 | K40: 0.77083333 | L40: =IF(("7:00"-J40)<=0,0,("7:00"-J40)) -> 0 | M40: =IF((K40-"18:00")<=0,0,(K40-"18:00")) -> 0.020833333 | O40: 100000 | P40: =N40*O40 -> 0 | X40: =W40*50000 -> 0 | Z40: =SUM(I40+P40+Q40+S40+V40+X40+Y40) -> 0
...

Sheet BẢNG KÊ THỰC TẾ 
A1: CÔNG TY TNHH XÂY DỰNG VÀ VẬN TẢI ĐỨC HUY | P1: Cộng Hòa Xã Hội Chủ Nghĩa Việt Nam
A2: ĐC: Xóm sến, Thôn hùng lãm 3,Xã hồng thái, Huyện việt yên, Tỉnh bắc giang, Việt nam. | P2: Độc Lập - Tự Do - Hạnh Phúc
A3: BẢNG ĐỐI CHIẾU KHỐI LƯỢNG VÀ GIÁ TRỊ SỬ DỤNG XE Ô TÔ 租车使用对账明细表
A4: Tháng 11 năm 2022 2022年11月
A5: Loại xe: 07 chỗ ngồi- BKS: 98A36900
A6: Khách hàng客户: CÔNG TY TNHH CÔNG NGHIỆP NIENYI VIỆT NAM
V7: ĐVT: VND
A8: NGÀY 日期 | B8: Km đầu 开始公里 | C8: Km cuối 结束公里 | D8: SỐ KM 使用公里数 | E8: SỐ KM TRỌN GÓI THEO HỢP ĐỒNG 按合同的公里数 | G8: KM PHỤ TRỘI NGÀY THƯỜNG 平日超过公里数 | J8: Giờ B.Đầu 开始时间 | K8: Giờ K.Thúc 结束时间 | N8: GIỜ PHỤ TRỘI NGÀY THƯỜNG 平日超过时间 | Q8: NGÀY CHỦ NHẬT /NGÀY LỄ | R8: ĐƠN GIÁ NGÀY CN/LỄ 礼拜天或节日的单价 | U8: GIỜ PHỤ TRỘI NGÀY CHỦ NHẬT/LỄ 礼拜天或节日超过时间 | W8: TIỀN ĂN 餐费 | Y8: TIỀN VÉ XE 过路费、车票 | Z8: CỘNG 合计
E9: SỐ KM 公里数 | F9: GIÁ TRỊ 金额 | G9: SỐ KM PHỤ TRỘI 超过公里数 | H9: ĐƠN GIÁ 单价 | I9: THÀNH TIỀN 金额 | N9: GIỜ 工时 | O9: ĐƠN GIÁ 单价 | P9: THÀNH TIÊN 金额 | R9: GIỜ 工时 | S9: ĐƠN GIÁ 单价 | T9: THÀNH TIỀN 金额 | U9: ĐƠN GIÁ 单价 | V9: THÀNH TIỀN 金额 | W9: SỐ BỮA ĂN 餐数量 | X9: THÀNH TIỀN 金额
E10: 3000 | F10: 25000000 | G10: =D42-E10 -> 3207 | H10: 6500 | I10: =G10*H10 -> 20845500 | N10: 1 | Q10: 0 | U10: 0 | V10: =T10*U10 -> 0 | Z10: =F10+I10+P10+Q10+S10+V10+X10+Y10 -> 45845500
A11: 44866 | B11: 67125 | C11: 67608 | D11: =C11-B11 -> 483 | J11: 0.3125 | K11: 20:30 | L11: =IF(("7:00"-J11)<=0,0,("7:00"-J11)) -> 0 | M11: =IF((K11-"18:00")<=0,0,(K11-"18:00")) -> 0.10416667 | N11: 1 | O11: 100000 | P11: =N11*O11 -> 100000 | X11: =W11*50000 -> 0 | Y11: =444000+50000 -> 494000 | Z11: =SUM(I11+P11+Q11+V11+X11+Y11+T11) -> 594000
A12: 44867 | B12: 67612 | C12: 67747 | D12: =C12-B12 -> 135 | J12: 0.3125 | K12: 0.9375 | L12: =IF(("7:00"-J12)<=0,0,("7:00"-J12)) -> 0 | M12: =IF((K12-"18:00")<=0,0,(K12-"18:00")) -> 0.1875 | N12: 1 | O12: =25000+100000 -> 125000 | P12: =N12*O12 -> 125000 | X12: =W12*50000 -> 0 | Z12: =SUM(I12+P12+Q12+V12+X12+Y12+T12) -> 125000
A13: 44868 | B13: 67751 | C13: 68061 | D13: =C13-B13 -> 310 | J13: 0.3125 | K13: 0.85416667 | L13: =IF(("7:00"-J13)<=0,0,("7:00"-J13)) -> 0 | M13: =IF((K13-"18:00")<=0,0,(K13-"18:00")) -> 0.10416667 | N13: 1 | O13: 100000 | P13: =N13*O13 -> 100000 | X13: =W13*50000 -> 0 | Y13: 100000 | Z13: =SUM(I13+P13+Q13+V13+X13+Y13+T13) -> 200000
A14: 44869 | B14: 68064 | C14: 68480 | D14: =C14-B14 -> 416 | J14: 0.27083333 | K14: 0.85416667 | L14: =IF(("7:00"-J14)<=0,0,("7:00"-J14)) -> 0.020833333 | M14: =IF((K14-"18:00")<=0,0,(K14-"18:00")) -> 0.10416667 | N14: 1 | O14: =25000+100000 -> 125000 | P14: =N14*O14 -> 125000 | W14: 1 | X14: =W14*50000 -> 50000 | Y14: =266000+50000 -> 316000 | Z14: =SUM(I14+P14+Q14+V14+X14+Y14+T14) -> 491000
A15: 44870 | B15: 68485 | C15: 68584 | D15: =C15-B15 -> 99 | J15: 0.3125 | K15: 0.77083333 | L15: =IF(("7:00"-J15)<=0,0,("7:00"-J15)) -> 0 | M15: =IF((K15-"18:00")<=0,0,(K15-"18:00")) -> 0.020833333 | N15: 1 | O15: 100000 | P15: =N15*O15 -> 100000 | X15: =W15*50000 -> 0 | Z15: =SUM(I15+P15+Q15+V15+X15+Y15+T15) -> 100000
A16: 44871 | B16: 0 | C16: 0 | D16: =C16-B16 -> 0 | J16: 0 | K16: 0 | L16: =IF(("7:00"-J16)<=0,0,("7:00"-J16)) -> 0.29166667 | M16: =IF((K16-"18:00")<=0,0,(K16-"18:00")) -> 0 | N16: 0 | O16: 100000 | P16: =N16*O16 -> 0 | X16: =W16*50000 -> 0 | Z16: =SUM(I16+P16+Q16+V16+X16+Y16+T16) -> 0
A17: 44872 | B17: 68615 | C17: 68779 | D17: =C17-B17 -> 164 | J17: 0.3125 | K17: 0.85416667 | L17: =IF(("7:00"-J17)<=0,0,("7:00"-J17)) -> 0 | M17: =IF((K17-"18:00")<=0,0,(K17-"18:00")) -> 0.10416667 | N17: 1 | O17: 100000 | P17: =N17*O17 -> 100000 | X17: =W17*50000 -> 0 | Z17: =SUM(I17+P17+Q17+V17+X17+Y17+T17) -> 100000
A18: 44873 | B18: 68784 | C18: 68917 | D18: =C18-B18 -> 133 | J18: 0.3125 | K18: 0.85416667 | L18: =IF(("7:00"-J18)<=0,0,("7:00"-J18)) -> 0 | M18: =IF((K18-"18:00")<=0,0,(K18-"18:00")) -> 0.10416667 | N18: 1 | O18: 100000 | P18: =N18*O18 -> 100000 | X18: =W18*50000 -> 0 | Z18: =SUM(I18+P18+Q18+V18+X18+Y18+T18) -> 100000
A19: 44874 | B19: 68922 | C19: 69049 | D19: =C19-B19 -> 127 | J19: 0.3125 | K19: 0.85416667 | L19: =IF(("7:00"-J19)<=0,0,("7:00"-J19)) -> 0 | M19: =IF((K19-"18:00")<=0,0,(K19-"18:00")) -> 0.10416667 | N19: 1 | O19: 100000 | P19: =N19*O19 -> 100000 | X19: =W19*50000 -> 0 | Z19: =SUM(I19+P19+Q19+V19+X19+Y19+T19) -> 100000
A20: 44875 | B20: 69054 | C20: 69206 | D20: =C20-B20 -> 152 | J20: 0.3125 | K20: 0.85416667 | L20: =IF(("7:00"-J20)<=0,0,("7:00"-J20)) -> 0 | M20: =IF((K20-"18:00")<=0,0,(K20-"18:00")) -> 0.10416667 | N20: 1 | O20: 100000 | P20: =N20*O20 -> 100000 | X20: =W20*50000 -> 0 | Z20: =SUM(I20+P20+Q20+V20+X20+Y20+T20) -> 100000
A21: 44876 | B21: 69210 | C21: 69343 | D21: =C21-B21 -> 133 | J21: 0.3125 | K21: 0.89583333 | L21: =IF(("7:00"-J21)<=0,0,("7:00"-J21)) -> 0 | M21: =IF((K21-"18:00")<=0,0,(K21-"18:00")) -> 0.14583333 | N21: 1 | O21: 100000 | P21: =N21*O21 -> 100000 | X21: =W21*50000 -> 0 | Z21: =SUM(I21+P21+Q21+V21+X21+Y21+T21) -> 100000
A22: 44877 | B22: 69347 | C22: 69508 | D22: =C22-B22 -> 161 | J22: 0.3125 | K22: 0.97916667 | L22: =IF(("7:00"-J22)<=0,0,("7:00"-J22)) -> 0 | M22: =IF((K22-"18:00")<=0,0,(K22-"18:00")) -> 0.22916667 | N22: 1 | O22: =75000+100000 -> 175000 | P22: =N22*O22 -> 175000 | X22: =W22*50000 -> 0 | Z22: =SUM(I22+P22+Q22+V22+X22+Y22+T22) -> 175000
A23: 44878 | B23: 0 | C23: 0 | D23: =C23-B23 -> 0 | J23: 0 | K23: 0 | L23: =IF(("7:00"-J23)<=0,0,("7:00"-J23)) -> 0.29166667 | M23: =IF((K23-"18:00")<=0,0,(K23-"18:00")) -> 0 | N23: 0 | O23: 100000 | P23: =N23*O23 -> 0 | X23: =W23*50000 -> 0 | Z23: =SUM(I23+P23+Q23+V23+X23+Y23+T23) -> 0
A24: 44879 | B24: 69522 | C24: 69646 | D24: =C24-B24 -> 124 | J24: 0.3125 | K24: 0.85416667 | L24: =IF(("7:00"-J24)<=0,0,("7:00"-J24)) -> 0 | M24: =IF((K24-"18:00")<=0,0,(K24-"18:00")) -> 0.10416667 | N24: 1 | O24: 100000 | P24: =N24*O24 -> 100000 | X24: =W24*50000 -> 0 | Z24: =SUM(I24+P24+Q24+V24+X24+Y24+T24) -> 100000
A25: 44880 | B25: 69650 | C25: 69861 | D25: =C25-B25 -> 211 | J25: 0.3125 | K25: 0.85416667 | L25: =IF(("7:00"-J25)<=0,0,("7:00"-J25)) -> 0 | M25: =IF((K25-"18:00")<=0,0,(K25-"18:00")) -> 0.10416667 | N25: 1 | O25: 100000 | P25: =N25*O25 -> 100000 | X25: =W25*50000 -> 0 | Z25: =SUM(I25+P25+Q25+V25+X25+Y25+T25) -> 100000
A26: 44881 | B26: 69865 | C26: 70119 | D26: =C26-B26 -> 254 | J26: 0.3125 | K26: 0.85416667 | L26: =IF(("7:00"-J26)<=0,0,("7:00"-J26)) -> 0 | M26: =IF((K26-"18:00")<=0,0,(K26-"18:00")) -> 0.10416667 | N26: 1 | O26: 100000 | P26: =N26*O26 -> 100000 | W26: 1 | X26: =W26*50000 -> 50000 | Y26: 17000 | Z26: =SUM(I26+P26+Q26+V26+X26+Y26+T26) -> 167000
A27: 44882 | B27: 70123 | C27: 70341 | D27: =C27-B27 -> 218 | J27: 0.3125 | K27: 0.85416667 | L27: =IF(("7:00"-J27)<=0,0,("7:00"-J27)) -> 0 | M27: =IF((K27-"18:00")<=0,0,(K27-"18:00")) -> 0.10416667 | N27: 1 | O27: 100000 | P27: =N27*O27 -> 100000 | X27: =W27*50000 -> 0 | Z27: =SUM(I27+P27+Q27+V27+X27+Y27+T27) -> 100000
A28: 44883 | B28: 70345 | C28: 70578 | D28: =C28-B28 -> 233 | J28: 0.3125 | K28: 0.85416667 | L28: =IF(("7:00"-J28)<=0,0,("7:00"-J28)) -> 0 | M28: =IF((K28-"18:00")<=0,0,(K28-"18:00")) -> 0.10416667 | N28: 1 | O28: 100000 | P28: =N28*O28 -> 100000 | X28: =W28*50000 -> 0 | Z28: =SUM(I28+P28+Q28+V28+X28+Y28+T28) -> 100000
A29: 44884 | B29: 70582 | C29: 70701 | D29: =C29-B29 -> 119 | J29: 0.3125 | K29: 0.85416667 | L29: =IF(("7:00"-J29)<=0,0,("7:00"-J29)) -> 0 | M29: =IF((K29-"18:00")<=0,0,(K29-"18:00")) -> 0.10416667 | N29: 1 | O29: 100000 | P29: =N29*O29 -> 100000 | X29: =W29*50000 -> 0 | Z29: =SUM(I29+P29+Q29+V29+X29+Y29+T29) -> 100000
A30: 44885 | B30: 0 | C30: 0 | D30: =C30-B30 -> 0 | J30: 0 | K30: 0 | L30: =IF(("7:00"-J30)<=0,0,("7:00"-J30)) -> 0.29166667 | M30: =IF((K30-"18:00")<=0,0,(K30-"18:00")) -> 0 | N30: 0 | O30: 100000 | P30: =N30*O30 -> 0 | X30: =W30*50000 -> 0 | Z30: =SUM(I30+P30+Q30+V30+X30+Y30+T30) -> 0
A31: 44886 | B31: 70725 | C31: 71124 | D31: =C31-B31 -> 399 | J31: 0.20833333 | K31: 0.85416667 | L31: =IF(("7:00"-J31)<=0,0,("7:00"-J31)) -> 0.083333333 | M31: =IF((K31-"18:00")<=0,0,(K31-"18:00")) -> 0.10416667 | N31: 1 | O31: 200000 | P31: =N31*O31 -> 200000 | X31: =W31*50000 -> 0 | Y31: 444000 | Z31: =SUM(I31+P31+Q31+V31+X31+Y31+T31) -> 644000
A32: 44887 | B32: 71128 | C32: 71236 | D32: =C32-B32 -> 108 | J32: 0.3125 | K32: 0.89583333 | L32: =IF(("7:00"-J32)<=0,0,("7:00"-J32)) -> 0 | M32: =IF((K32-"18:00")<=0,0,(K32-"18:00")) -> 0.14583333 | N32: 1 | O32: 100000 | P32: =N32*O32 -> 100000 | X32: =W32*50000 -> 0 | Z32: =SUM(I32+P32+Q32+V32+X32+Y32+T32) -> 100000
A33: 44888 | B33: 71239 | C33: 71366 | D33: =C33-B33 -> 127 | J33: 0.3125 | K33: 0.89583333 | L33: =IF(("7:00"-J33)<=0,0,("7:00"-J33)) -> 0 | M33: =IF((K33-"18:00")<=0,0,(K33-"18:00")) -> 0.14583333 | N33: 1 | O33: 100000 | P33: =N33*O33 -> 100000 | X33: =W33*50000 -> 0 | Z33: =SUM(I33+P33+Q33+V33+X33+Y33+T33) -> 100000
A34: 44889 | B34: 71370 | C34: 71479 | D34: =C34-B34 -> 109 | J34: 0.3125 | K34: 0.89583333 | N34: 1 | O34: 100000 | P34: =N34*O34 -> 100000 | X34: =W34*50000 -> 0 | Z34: =SUM(I34+P34+Q34+V34+X34+Y34+T34) -> 100000
A35: 44890 | B35: 71483 | C35: 71894 | D35: =C35-B35 -> 411 | J35: 0.3125 | K35: 0.89583333 | L35: =IF(("7:00"-J35)<=0,0,("7:00"-J35)) -> 0 | M35: =IF((K35-"18:00")<=0,0,(K35-"18:00")) -> 0.14583333 | N35: 1 | O35: 100000 | P35: =N35*O35 -> 100000 | W35: 1 | X35: =W35*50000 -> 50000 | Y35: 246000 | Z35: =SUM(I35+P35+Q35+V35+X35+Y35+T35) -> 396000
A36: 44891 | B36: 71897 | C36: 72316 | D36: =C36-B36 -> 419 | J36: 0.3125 | K36: 0.89583333 | N36: 1 | O36: 100000 | P36: =N36*O36 -> 100000 | W36: 1 | X36: =W36*50000 -> 50000 | Y36: =50000+21000+70000 -> 141000 | Z36: =SUM(I36+P36+Q36+V36+X36+Y36+T36) -> 291000
A37: 44892 | B37: 72365 | C37: 72603 | D37: =C37-B37 -> 238 | J37: 0.875 | K37: 0.10416667 | L37: =IF(("7:00"-J37)<=0,0,("7:00"-J37)) -> 0 | M37: =IF((K37-"18:00")<=0,0,(K37-"18:00")) -> 0 | N37: 1 | O37: 275000 | P37: =N37*O37 -> 275000 | X37: =W37*50000 -> 0 | Y37: =25000+70000 -> 95000 | Z37: =SUM(I37+P37+Q37+V37+X37+Y37+T37) -> 370000
A38: 44893 | B38: 72608 | C38: 72791 | D38: =C38-B38 -> 183 | J38: 0.3125 | K38: 0.89583333 | L38: =IF(("7:00"-J38)<=0,0,("7:00"-J38)) -> 0 | M38: =IF((K38-"18:00")<=0,0,(K38-"18:00")) -> 0.14583333 | N38: 1 | O38: 100000 | P38: =N38*O38 -> 100000 | X38: =W38*50000 -> 0 | Z38: =SUM(I38+P38+Q38+V38+X38+Y38+T38) -> 100000
A39: 44894 | B39: 72795 | C39: 73149 | D39: =C39-B39 -> 354 | J39: 0.3125 | K39: 0.89583333 | L39: =IF(("7:00"-J39)<=0,0,("7:00"-J39)) -> 0 | M39: =IF((K39-"18:00")<=0,0,(K39-"18:00")) -> 0.14583333 | N39: 1 | O39: 100000 | P39: =N39*O39 -> 100000 | W39: 1 | X39: =W39*50000 -> 50000 | Y39: =70000+60000 -> 130000 | Z39: =SUM(I39+P39+Q39+V39+X39+Y39+T39) -> 280000
A40: 44895 | B40: 73154 | C40: =B40+387 -> 73541 | D40: =C40-B40 -> 387 | J40: 0.22916667 | K40: 0.85416667 | L40: =IF(("7:00"-J40)<=0,0,("7:00"-J40)) -> 0.0625 | M40: =IF((K40-"18:00")<=0,0,(K40-"18:00")) -> 0.10416667 | N40: 1 | O40: 175000 | P40: =N40*O40 -> 175000 | W40: 2 | X40: =W40*50000 -> 100000 | Y40: 196000 | Z40: =SUM(I40+P40+Q40+V40+X40+Y40+T40) -> 471000
...

Sheet Kangatang

Sheet Kangatang_2

Sheet Kangatang_3

Sheet ĐNTT
A1: 2026 年07月份的对账单 BẢNG ĐỐI CHIẾU CÔNG NỢ CƯỚC XE THÁNG 07/2026
A3: BÊN VẬN CHUYỂN: CÔNG TY TNHH KINH DOANH DỊCH VỤ VẬN TẢI ĐỨC ANH
A5: Địa chỉ : Số 7, Tổ dân phố Hoàng Mai 1, Phường Nếnh, Tỉnh Bắc Ninh, Việt Nam.
A6: MST: 2401073432
A7: Số tài khoản: 1507438888 tại ngân hàng Vietcombank - Chi nhánh Tây Bắc Ninh.
A8: BÊN THUÊ VẬN CHUYỂN: CÔNG TY TNHH CÔNG NGHIỆP NIENYI VIỆT NAM
A9: Địa chỉ : Nhà xưởng CN-09-08, CN-09-09, Lô CN-09, Khu công nghiệp Vân Trung, Phường Nếnh, Tỉnh Bắc Ninh, Việt Nam.
A10: MST: 2400 860 701 nienyithanhtoan@gmail.com
A11: Phí vận chuyển hàng bằng xe tải 8 tấn:
A12: 内容 Nội dung | C12: 数量 Số lượng | D12: 金额 Số tiền
A13: Số Km thực tế | B13: 实际公里数
A14: Số ngày thực tế | B14: 实际天数 | C14: 26 | D14: 42000000
A15: Chi phí tăng ca (Trước 8h00AM và sau 18h00 PM) | B15: （8:00之前和早上18:00之后晚上） | C15: 16 | D15: =C15*50000 -> 800000
A16: Số giờ ngày Chủ nhật, Ngày lễ | B16: 星期天的数量时间
A17: Số KM phát sinh | B17: 出现的KM号码 | D17: =C17*6500 -> 0
A18: Số KM phát sinh CN | B18: 产生的公里数
A19: Ngày chủ nhật di làm | B19: 产生的公里数
A20: Lưu đêm | B20: 一夜之间 | D20: ='BẢNG KÊ CHI TIẾT XUẤT VAT 07'!R42 -> 0
A21: Nội bài (ngày nghỉ) / 1 lần | B21: 机场（假日）/ 1次
A22: Vé cầu đường, phí gửi xe | B22: 路票，停车费 | D22: =+'BẢNG KÊ CHI TIẾT XUẤT VAT 07'!AA42 -> 0
A23: Khác ( Ăn trưa) | B23: 其他（午餐） | C23: =+'BẢNG KÊ CHI TIẾT XUẤT VAT 07'!Y42 -> 9 | D23: =+'BẢNG KÊ CHI TIẾT XUẤT VAT 07'!Z42 -> 450000
A24: Giờ phụ trội ngày chủ nhật / lễ | B24: 礼拜天或节日超过时间 | D24: =+'BẢNG KÊ CHI TIẾT XUẤT VAT 07'!X42 -> 0
A25: Cộng tiền hàng | B25: 金额 | D25: =SUM(D13:D24) -> 43250000
A26: Thuế GTGT 0% | B26: 0％增值税 | D26: 0
A27: Tổng tiền thanh toán | B27: 合计 | D27: =D25+D26 -> 43250000
A28: Bằng chữ: | B28: Bốn mươi ba triệu hai trăm năm mươi nghìn đồng.
B29: Bắc Ninh, ngày 25 tháng 07 năm 2026
A30: 承租人Người mua hàng | B30: 出租人 Người bán hàng
A31: 签名(Ký, ghi rõ họ tên) | B31: 签名(Ký, ghi rõ họ tên)

Sheet BẢNG KÊ CHI TIẾT XE TDP 08
A1: CÔNG TY TNHH 98 AN PHÁT | P1: Cộng Hòa Xã Hội Chủ Nghĩa Việt Nam
A2: ĐC: Thôn Đức Liễn – Xã Hồng Thái – Huyện Việt Yên – Tỉnh Bắc Giang–Việt Nam. | P2: Độc Lập - Tự Do - Hạnh Phúc
A3: BẢNG ĐỐI CHIẾU KHỐI LƯỢNG VÀ GIÁ TRỊ SỬ DỤNG XE Ô TÔ 租车使用对账明细表
A4: Tháng 08 năm 2023 2023年8月
A5: Loại xe: 07 chỗ ngồi- BKS: 98A36900
A6: Khách hàng客户: CÔNG TY TNHH CÔNG NGHIỆP NIENYI VIỆT NAM
V7: ĐVT: VND
A8: NGÀY 日期 | B8: Km đầu 开始公里 | C8: Km cuối 结束公里 | D8: SỐ KM 使用公里数 | E8: SỐ KM TRỌN GÓI THEO HỢP ĐỒNG 按合同的公里数 | G8: KM PHỤ TRỘI NGÀY THƯỜNG 平日超过公里数 | J8: Giờ B.Đầu 开始时间 | K8: Giờ K.Thúc 结束时间 | L8: Số giờ tăng ca | N8: GIỜ PHỤ TRỘI NGÀY THƯỜNG 平日超过时间 | Q8: ĐƠN GIÁ NGÀY QUA ĐÊM 过夜单价 | R8: ĐƠN GIÁ NGÀY CN/LỄ 礼拜天或节日的单价 | U8: GIỜ PHỤ TRỘI NGÀY CHỦ NHẬT/LỄ 礼拜天或节日超过时间 | W8: TIỀN ĂN 餐费 | Y8: TIỀN VÉ XE 过路费、车票 | Z8: CỘNG 合计
E9: SỐ KM 公里数 | F9: GIÁ TRỊ 金额 | G9: SỐ KM PHỤ TRỘI 超过公里数 | H9: ĐƠN GIÁ 单价 | I9: THÀNH TIỀN 金额 | N9: GIỜ 工时 | O9: ĐƠN GIÁ 单价 | P9: THÀNH TIÊN 金额 | R9: GIỜ 工时 | S9: ĐƠN GIÁ 单价 | T9: THÀNH TIỀN 金额 | U9: ĐƠN GIÁ 单价 | V9: THÀNH TIỀN 金额 | W9: SỐ BỮA ĂN 餐数量 | X9: THÀNH TIỀN 金额
E10: 3000 | F10: 25000000 | G10: =+D42-E10 -> 3431 | H10: 6500 | I10: =G10*H10 -> 22301500 | Z10: =F10+I10+P10+Q10+S10+V10+X10+Y10 -> 47301500
A11: 45139 | B11: 128902 | C11: 129242 | D11: =C11-B11 -> 340 | J11: 0.29166667 | K11: 0 | L11: 2 | N11: 1 | O11: =100000+100000 -> 200000 | P11: =N11*O11 -> 200000 | W11: 1 | X11: =W11*50000 -> 50000 | Y11: 70000 | Z11: =SUM(I11+P11+Q11+V11+X11+Y11+T11) -> 320000
A12: 45140 | B12: 129246 | C12: 129428 | D12: =C12-B12 -> 182 | J12: 0.29166667 | K12: 0.83333333 | N12: 1 | O12: 100000 | P12: =N12*O12 -> 100000 | X12: =W12*50000 -> 0 | Y12: 30000 | Z12: =SUM(I12+P12+Q12+V12+X12+Y12+T12) -> 130000
A13: 45141 | B13: 129432 | C13: 129616 | D13: =C13-B13 -> 184 | J13: 0.29166667 | K13: 0.83333333 | N13: 1 | O13: 100000 | P13: =N13*O13 -> 100000 | X13: =W13*50000 -> 0 | Z13: =SUM(I13+P13+Q13+V13+X13+Y13+T13) -> 100000
A14: 45142 | B14: 129622 | C14: 129773 | D14: =C14-B14 -> 151 | J14: 0.29166667 | K14: 0.85416667 | N14: 1 | O14: 100000 | P14: =N14*O14 -> 100000 | X14: =W14*50000 -> 0 | Z14: =SUM(I14+P14+Q14+V14+X14+Y14+T14) -> 100000
A15: 45143 | B15: 129781 | C15: 130141 | D15: =C15-B15 -> 360 | J15: 0.22916667 | K15: 0.66666667 | L15: 1.5 | O15: 75000 | P15: =O15 -> 75000 | X15: =W15*50000 -> 0 | Y15: 18000 | Z15: =SUM(I15+P15+Q15+V15+X15+Y15+T15) -> 93000
A16: 45144 | D16: =C16-B16 -> 0 | O16: 100000 | P16: =N16*O16 -> 0 | X16: =W16*50000 -> 0 | Z16: =SUM(I16+P16+Q16+V16+X16+Y16+T16) -> 0
A17: 45145 | B17: 130148 | C17: 130349 | D17: =C17-B17 -> 201 | J17: 0.29166667 | K17: 0.89583333 | N17: 1 | O17: 100000 | P17: =N17*O17 -> 100000 | X17: =W17*50000 -> 0 | Z17: =SUM(I17+P17+Q17+V17+X17+Y17+T17) -> 100000
A18: 45146 | B18: 130354 | C18: 130638 | D18: =C18-B18 -> 284 | J18: 0.29166667 | K18: 0.85416667 | N18: 1 | O18: 100000 | P18: =N18*O18 -> 100000 | X18: =W18*50000 -> 0 | Y18: =70000+50000 -> 120000 | Z18: =SUM(I18+P18+Q18+V18+X18+Y18+T18) -> 220000
A19: 45147 | B19: 130642 | C19: 130737 | D19: =C19-B19 -> 95 | J19: 0.29166667 | K19: 0.83333333 | N19: 1 | O19: 100000 | P19: =N19*O19 -> 100000 | X19: =W19*50000 -> 0 | Z19: =SUM(I19+P19+Q19+V19+X19+Y19+T19) -> 100000 | AA19: 1
A20: 45148 | B20: 130741 | C20: 130875 | D20: =C20-B20 -> 134 | J20: 0.29166667 | K20: 0.85416667 | N20: 1 | O20: 100000 | P20: =N20*O20 -> 100000 | X20: =W20*50000 -> 0 | Z20: =SUM(I20+P20+Q20+V20+X20+Y20+T20) -> 100000
A21: 45149 | B21: 130879 | C21: 130951 | D21: =C21-B21 -> 72 | J21: 0.29166667 | K21: 0.85416667 | N21: 1 | O21: 100000 | P21: =N21*O21 -> 100000 | X21: =W21*50000 -> 0 | Z21: =SUM(I21+P21+Q21+V21+X21+Y21+T21) -> 100000
A22: 45150 | B22: 130956 | C22: 131170 | D22: =C22-B22 -> 214 | J22: 0.20833333 | K22: 0.79166667 | L22: 2 | N22: 1 | O22: =100000+100000 -> 200000 | P22: =N22*O22 -> 200000 | X22: =W22*50000 -> 0 | Y22: 9000 | Z22: =SUM(I22+P22+Q22+V22+X22+Y22+T22) -> 209000 | AC22: từ 7h30 đến 18h là 10.5 tiếng, anh ngọc đi 9h đến 18h là 8 tiếng
A23: 45151 | B23: 131178 | C23: 131336 | D23: =C23-B23 -> 158 | J23: 0.64583333 | K23: 0.77083333 | L23: 0.5 | O23: =0.5*50000 -> 25000 | P23: 25000 | R23: 2.5 | S23: =1000000/8 -> 125000 | T23: =R23*S23 -> 312500 | X23: =W23*50000 -> 0 | Y23: 13000 | Z23: =SUM(I23+P23+Q23+V23+X23+Y23+T23) -> 350500
A24: 45152 | B24: 131340 | C24: 131579 | D24: =C24-B24 -> 239 | J24: 0.29166667 | K24: 0.85416667 | N24: 1 | O24: 100000 | P24: =N24*O24 -> 100000 | X24: =W24*50000 -> 0 | Z24: =SUM(I24+P24+Q24+V24+X24+Y24+T24) -> 100000
A25: 45153 | B25: 131583 | C25: 131841 | D25: =C25-B25 -> 258 | J25: 0.29166667 | K25: 0.85416667 | N25: 1 | O25: 100000 | P25: =N25*O25 -> 100000 | W25: 1 | X25: =W25*50000 -> 50000 | Z25: =SUM(I25+P25+Q25+V25+X25+Y25+T25) -> 150000
A26: 45154 | B26: 131846 | C26: 132011 | D26: =C26-B26 -> 165 | J26: 0.29166667 | K26: 0.83333333 | N26: 1 | O26: 100000 | P26: =N26*O26 -> 100000 | W26: 1 | X26: =W26*50000 -> 50000 | Z26: =SUM(I26+P26+Q26+V26+X26+Y26+T26) -> 150000
A27: 45155 | B27: 132015 | C27: 132227 | D27: =C27-B27 -> 212 | J27: 0.29166667 | K27: 0.89583333 | N27: 1 | O27: 100000 | P27: =N27*O27 -> 100000 | W27: 1 | X27: =W27*50000 -> 50000 | Z27: =SUM(I27+P27+Q27+V27+X27+Y27+T27) -> 150000
A28: 45156 | B28: 132234 | C28: 132503 | D28: =C28-B28 -> 269 | J28: 0.29166667 | K28: 0 | L28: 2 | N28: 1 | O28: =100000+100000 -> 200000 | P28: =N28*O28 -> 200000 | W28: 1 | X28: =W28*50000 -> 50000 | Z28: =SUM(I28+P28+Q28+V28+X28+Y28+T28) -> 250000
A29: 45157 | B29: 132508 | C29: 132871 | D29: =C29-B29 -> 363 | J29: 0.29166667 | K29: 0.125 | L29: 2 | N29: 1 | O29: =100000+100000 -> 200000 | P29: =N29*O29 -> 200000 | Q29: 300000 | X29: =W29*50000 -> 0 | Z29: =SUM(I29+P29+Q29+V29+X29+Y29+T29) -> 500000
A30: 45158 | D30: =C30-B30 -> 0 | O30: 100000 | P30: =N30*O30 -> 0 | X30: =W30*50000 -> 0 | Z30: =SUM(I30+P30+Q30+V30+X30+Y30+T30) -> 0
A31: 45159 | B31: 132886 | C31: 133141 | D31: =C31-B31 -> 255 | J31: 0.29166667 | K31: 0.85416667 | N31: 1 | O31: 100000 | P31: =N31*O31 -> 100000 | X31: =W31*50000 -> 0 | Z31: =SUM(I31+P31+Q31+V31+X31+Y31+T31) -> 100000
A32: 45160 | B32: 133146 | C32: 133276 | D32: =C32-B32 -> 130 | J32: 0.29166667 | K32: 0.85416667 | N32: 1 | O32: 100000 | P32: =N32*O32 -> 100000 | X32: =W32*50000 -> 0 | Z32: =SUM(I32+P32+Q32+V32+X32+Y32+T32) -> 100000
A33: 45161 | B33: 133280 | C33: 133497 | D33: =C33-B33 -> 217 | J33: 0.29166667 | K33: 0.85416667 | N33: 1 | O33: 100000 | P33: =N33*O33 -> 100000 | X33: =W33*50000 -> 0 | Z33: =SUM(I33+P33+Q33+V33+X33+Y33+T33) -> 100000
A34: 45162 | B34: 133502 | C34: 133900 | D34: =C34-B34 -> 398 | J34: 0.25 | K34: 0.95833333 | L34: =1+1 -> 2 | N34: 1 | O34: =100000+100000 -> 200000 | P34: =N34*O34 -> 200000 | W34: 2 | X34: =W34*50000 -> 100000 | Y34: =70000+9000 -> 79000 | Z34: =SUM(I34+P34+Q34+V34+X34+Y34+T34) -> 379000
A35: 45163 | B35: 133904 | C35: 134252 | D35: =C35-B35 -> 348 | J35: 0.29166667 | K35: 0.95833333 | L35: 1 | N35: 1 | O35: =50000+100000 -> 150000 | P35: =N35*O35 -> 150000 | W35: 1 | X35: =W35*50000 -> 50000 | Y35: =70000+50000+13000 -> 133000 | Z35: =SUM(I35+P35+Q35+V35+X35+Y35+T35) -> 333000
A36: 45164 | B36: 134259 | C36: 134493 | D36: =C36-B36 -> 234 | J36: 0.25 | K36: 0.8125 | L36: 1 | N36: 1 | O36: =50000+100000 -> 150000 | P36: =N36*O36 -> 150000 | X36: =W36*50000 -> 0 | Y36: 9000 | Z36: =SUM(I36+P36+Q36+V36+X36+Y36+T36) -> 159000
A37: 45165 | D37: =C37-B37 -> 0 | O37: 100000 | P37: =N37*O37 -> 0 | X37: =W37*50000 -> 0 | Z37: =SUM(I37+P37+Q37+V37+X37+Y37+T37) -> 0
A38: 45166 | B38: 134502 | C38: 134923 | D38: =C38-B38 -> 421 | J38: 0.29166667 | K38: 0.83333333 | N38: 1 | O38: 100000 | P38: =N38*O38 -> 100000 | W38: 1 | X38: =W38*50000 -> 50000 | Y38: 490000 | Z38: =SUM(I38+P38+Q38+V38+X38+Y38+T38) -> 640000
A39: 45167 | B39: 134928 | C39: 135198 | D39: =C39-B39 -> 270 | J39: 0.29166667 | K39: 0.85416667 | N39: 1 | O39: 100000 | P39: =N39*O39 -> 100000 | X39: =W39*50000 -> 0 | Z39: =SUM(I39+P39+Q39+V39+X39+Y39+T39) -> 100000
A40: 45168 | B40: 135202 | C40: 135367 | D40: =C40-B40 -> 165 | J40: 0.29166667 | K40: 0.85416667 | N40: 1 | O40: 100000 | P40: =N40*O40 -> 100000 | X40: =W40*50000 -> 0 | Z40: =SUM(I40+P40+Q40+V40+X40+Y40+T40) -> 100000 | AA40: sếp báo trả anh ngọc 700k ngày chủ nhật +tăng ca
...

Sheet xe nienyi 
A1: CÔNG TY TNHH XÂY DỰNG VÀ VẬN TẢI ĐỨC HUY | P1: Cộng Hòa Xã Hội Chủ Nghĩa Việt Nam
A2: ĐC: Xóm sến, Thôn hùng lãm 3,Xã hồng thái, Huyện việt yên, Tỉnh bắc giang, Việt nam. | P2: Độc Lập - Tự Do - Hạnh Phúc
A3: BẢNG ĐỐI CHIẾU KHỐI LƯỢNG VÀ GIÁ TRỊ SỬ DỤNG XE Ô TÔ 租车使用对账明细表
A4: Tháng 01 năm 2023 2023年1月
A5: Loại xe: 07 chỗ ngồi- BKS: 98A36900
A6: Khách hàng客户: CÔNG TY TNHH CÔNG NGHIỆP NIENYI VIỆT NAM
V7: ĐVT: VND
A8: NGÀY 日期 | B8: Km đầu 开始公里 | C8: Km cuối 结束公里 | D8: SỐ KM 使用公里数 | E8: SỐ KM TRỌN GÓI THEO HỢP ĐỒNG 按合同的公里数 | G8: KM PHỤ TRỘI NGÀY THƯỜNG 平日超过公里数 | J8: Giờ B.Đầu 开始时间 | K8: Giờ K.Thúc 结束时间 | N8: GIỜ PHỤ TRỘI NGÀY THƯỜNG 平日超过时间 | Q8: ĐƠN GIÁ NGÀY QUA ĐÊM 过夜单价 | R8: ĐƠN GIÁ NGÀY CN/LỄ 礼拜天或节日的单价 | U8: GIỜ PHỤ TRỘI NGÀY CHỦ NHẬT/LỄ 礼拜天或节日超过时间 | W8: TIỀN ĂN 餐费 | Y8: TIỀN VÉ XE 过路费、车票 | Z8: CỘNG 合计
E9: SỐ KM 公里数 | F9: GIÁ TRỊ 金额 | G9: SỐ KM PHỤ TRỘI 超过公里数 | H9: ĐƠN GIÁ 单价 | I9: THÀNH TIỀN 金额 | N9: GIỜ 工时 | O9: ĐƠN GIÁ 单价 | P9: THÀNH TIÊN 金额 | R9: GIỜ 工时 | S9: ĐƠN GIÁ 单价 | T9: THÀNH TIỀN 金额 | U9: ĐƠN GIÁ 单价 | V9: THÀNH TIỀN 金额 | W9: SỐ BỮA ĂN 餐数量 | X9: THÀNH TIỀN 金额
E10: 3000 | F10: 25000000 | H10: 6500 | I10: =G10*H10 -> 0 | N10: 1 | Q10: 0 | U10: 0 | V10: =T10*U10 -> 0 | Z10: =F10+I10+P10+Q10+S10+V10+X10+Y10 -> 25000000
A11: 44927 | D11: 0 | J11: 0 | K11: 0 | L11: =IF(("7:00"-J11)<=0,0,("7:00"-J11)) -> 0.29166667 | M11: =IF((K11-"18:00")<=0,0,(K11-"18:00")) -> 0 | N11: 0 | O11: 100000 | P11: =N11*O11 -> 0 | X11: =W11*50000 -> 0 | Z11: =SUM(I11+P11+Q11+V11+X11+Y11+T11) -> 0
A12: 44928 | D12: 0 | J12: 0 | K12: 0 | L12: =IF(("7:00"-J12)<=0,0,("7:00"-J12)) -> 0.29166667 | M12: =IF((K12-"18:00")<=0,0,(K12-"18:00")) -> 0 | N12: 0 | O12: 100000 | P12: =N12*O12 -> 0 | X12: =W12*50000 -> 0 | Z12: =SUM(I12+P12+Q12+V12+X12+Y12+T12) -> 0
A13: 44929 | B13: 81034 | C13: 81149 | D13: =C13-B13 -> 115 | J13: 0.3125 | K13: 0.85416667 | L13: =IF(("7:00"-J13)<=0,0,("7:00"-J13)) -> 0 | M13: =IF((K13-"18:00")<=0,0,(K13-"18:00")) -> 0.10416667 | N13: 1 | O13: 100000 | P13: =N13*O13 -> 100000 | X13: =W13*50000 -> 0 | Z13: =SUM(I13+P13+Q13+V13+X13+Y13+T13) -> 100000
A14: 44930 | B14: 81154 | C14: 81235 | D14: =C14-B14 -> 81 | J14: 0.3125 | K14: 0.85416667 | L14: =IF(("7:00"-J14)<=0,0,("7:00"-J14)) -> 0 | M14: =IF((K14-"18:00")<=0,0,(K14-"18:00")) -> 0.10416667 | N14: 1 | O14: 100000 | P14: =N14*O14 -> 100000 | X14: =W14*50000 -> 0 | Z14: =SUM(I14+P14+Q14+V14+X14+Y14+T14) -> 100000
A15: 44931 | B15: 81239 | C15: 81370 | D15: =C15-B15 -> 131 | J15: 0.3125 | K15: 0.85416667 | L15: =IF(("7:00"-J15)<=0,0,("7:00"-J15)) -> 0 | M15: =IF((K15-"18:00")<=0,0,(K15-"18:00")) -> 0.10416667 | N15: 1 | O15: 100000 | P15: =N15*O15 -> 100000 | X15: =W15*50000 -> 0 | Z15: =SUM(I15+P15+Q15+V15+X15+Y15+T15) -> 100000
A16: 44932 | B16: 81374 | C16: 81424 | D16: =C16-B16 -> 50 | J16: 0.3125 | K16: 0.85416667 | L16: =IF(("7:00"-J16)<=0,0,("7:00"-J16)) -> 0 | M16: =IF((K16-"18:00")<=0,0,(K16-"18:00")) -> 0.10416667 | N16: 1 | O16: 100000 | P16: =N16*O16 -> 100000 | X16: =W16*50000 -> 0 | Z16: =SUM(I16+P16+Q16+V16+X16+Y16+T16) -> 100000
A17: 44933 | B17: 81429 | C17: 81533 | D17: =C17-B17 -> 104 | J17: 0.3125 | K17: 0.8125 | L17: =IF(("7:00"-J17)<=0,0,("7:00"-J17)) -> 0 | M17: =IF((K17-"18:00")<=0,0,(K17-"18:00")) -> 0.0625 | N17: 1 | O17: 100000 | P17: =N17*O17 -> 100000 | X17: =W17*50000 -> 0 | Z17: =SUM(I17+P17+Q17+V17+X17+Y17+T17) -> 100000
A18: 44934 | B18: 81539 | C18: 81835 | D18: =C18-B18 -> 296 | J18: 0.25 | K18: 0.47916667 | L18: =IF(("7:00"-J18)<=0,0,("7:00"-J18)) -> 0.041666667 | M18: =IF((K18-"18:00")<=0,0,(K18-"18:00")) -> 0 | N18: 0 | O18: =+(1.5*50000) -> 75000 | P18: =O18 -> 75000 | R18: 4 | S18: =1000000/8 -> 125000 | T18: =R18*S18 -> 500000 | X18: =W18*50000 -> 0 | Y18: 270000 | Z18: =SUM(I18+P18+Q18+V18+X18+Y18+T18) -> 845000 | AA18: HE JIANG FEN+ CHEN MING+ZHANG LL VỀ NƯỚC (KÝ TÚC-HỮU NGHỊ)
A19: 44935 | B19: 81864 | C19: 81918 | D19: =C19-B19 -> 54 | J19: 0.3125 | K19: 0.89583333 | L19: =IF(("7:00"-J19)<=0,0,("7:00"-J19)) -> 0 | M19: =IF((K19-"18:00")<=0,0,(K19-"18:00")) -> 0.14583333 | N19: 1 | O19: 100000 | P19: =N19*O19 -> 100000 | X19: =W19*50000 -> 0 | Z19: =SUM(I19+P19+Q19+V19+X19+Y19+T19) -> 100000
A20: 44936 | B20: 81922 | C20: 82057 | D20: =C20-B20 -> 135 | J20: 0.3125 | K20: 0.875 | L20: =IF(("7:00"-J20)<=0,0,("7:00"-J20)) -> 0 | M20: =IF((K20-"18:00")<=0,0,(K20-"18:00")) -> 0.125 | N20: 1 | O20: 100000 | P20: =N20*O20 -> 100000 | X20: =W20*50000 -> 0 | Z20: =SUM(I20+P20+Q20+V20+X20+Y20+T20) -> 100000
A21: 44937 | B21: 82061 | C21: 82142 | D21: =C21-B21 -> 81 | J21: 0.3125 | K21: 0.875 | L21: =IF(("7:00"-J21)<=0,0,("7:00"-J21)) -> 0 | M21: =IF((K21-"18:00")<=0,0,(K21-"18:00")) -> 0.125 | N21: 1 | O21: 100000 | P21: =N21*O21 -> 100000 | X21: =W21*50000 -> 0 | Z21: =SUM(I21+P21+Q21+V21+X21+Y21+T21) -> 100000
A22: 44938 | B22: 82145 | C22: 82276 | D22: =C22-B22 -> 131 | J22: 0.3125 | K22: 0.89583333 | L22: =IF(("7:00"-J22)<=0,0,("7:00"-J22)) -> 0 | M22: =IF((K22-"18:00")<=0,0,(K22-"18:00")) -> 0.14583333 | N22: 1 | O22: 100000 | P22: =N22*O22 -> 100000 | X22: =W22*50000 -> 0 | Z22: =SUM(I22+P22+Q22+V22+X22+Y22+T22) -> 100000
A23: 44939 | B23: 82280 | C23: 82438 | D23: =C23-B23 -> 158 | J23: 0.3125 | K23: 0.89583333 | L23: =IF(("7:00"-J23)<=0,0,("7:00"-J23)) -> 0 | M23: =IF((K23-"18:00")<=0,0,(K23-"18:00")) -> 0.14583333 | N23: 1 | O23: 100000 | P23: =N23*O23 -> 100000 | X23: =W23*50000 -> 0 | Z23: =SUM(I23+P23+Q23+V23+X23+Y23+T23) -> 100000
A24: 44940 | B24: 82442 | C24: 82622 | D24: =C24-B24 -> 180 | J24: 0.3125 | K24: 0.85416667 | L24: =IF(("7:00"-J24)<=0,0,("7:00"-J24)) -> 0 | M24: =IF((K24-"18:00")<=0,0,(K24-"18:00")) -> 0.10416667 | N24: 1 | O24: 100000 | P24: =N24*O24 -> 100000 | X24: =W24*50000 -> 0 | Z24: =SUM(I24+P24+Q24+V24+X24+Y24+T24) -> 100000
A25: 44941 | B25: 82635 | C25: 82933 | D25: =C25-B25 -> 298 | J25: 0.25 | K25: 0.47916667 | L25: =IF(("7:00"-J25)<=0,0,("7:00"-J25)) -> 0.041666667 | M25: =IF((K25-"18:00")<=0,0,(K25-"18:00")) -> 0 | N25: 0 | O25: =+(1.5*50000) -> 75000 | P25: =O25 -> 75000 | R25: 4 | S25: =1000000/8 -> 125000 | T25: =R25*S25 -> 500000 | X25: =W25*50000 -> 0 | Y25: 270000 | Z25: =SUM(I25+P25+Q25+V25+X25+Y25+T25) -> 845000 | AA25: LIN ZHI PENG+ CHEN JI QING VỀ NƯỚC (KÝ TÚC-HỮU NGHỊ)
A26: 44942 | B26: 82937 | C26: 83049 | D26: =C26-B26 -> 112 | J26: 0.3125 | K26: 0.875 | L26: =IF(("7:00"-J26)<=0,0,("7:00"-J26)) -> 0 | M26: =IF((K26-"18:00")<=0,0,(K26-"18:00")) -> 0.125 | N26: 1 | O26: 100000 | P26: =N26*O26 -> 100000 | X26: =W26*50000 -> 0 | Z26: =SUM(I26+P26+Q26+V26+X26+Y26+T26) -> 100000
A27: 44943 | B27: 83062 | C27: 83367 | D27: =C27-B27 -> 305 | J27: 0.3125 | K27: 0.89583333 | L27: =IF(("7:00"-J27)<=0,0,("7:00"-J27)) -> 0 | M27: =IF((K27-"18:00")<=0,0,(K27-"18:00")) -> 0.14583333 | N27: 1 | O27: 100000 | P27: =N27*O27 -> 100000 | W27: 1 | X27: =W27*50000 -> 50000 | Y27: 70000 | Z27: =SUM(I27+P27+Q27+V27+X27+Y27+T27) -> 220000
A28: 44944 | B28: 83372 | C28: 83434 | D28: =C28-B28 -> 62 | J28: 0.3125 | K28: 0.77083333 | L28: =IF(("7:00"-J28)<=0,0,("7:00"-J28)) -> 0 | M28: =IF((K28-"18:00")<=0,0,(K28-"18:00")) -> 0.020833333 | N28: 1 | O28: 100000 | P28: =N28*O28 -> 100000 | X28: =W28*50000 -> 0 | Z28: =SUM(I28+P28+Q28+V28+X28+Y28+T28) -> 100000
A29: 44945 | B29: 83456 | C29: 83584 | D29: =C29-B29 -> 128 | J29: 0.625 | K29: 0.70833333 | L29: =IF(("7:00"-J29)<=0,0,("7:00"-J29)) -> 0 | M29: =IF((K29-"18:00")<=0,0,(K29-"18:00")) -> 0 | N29: 0 | O29: 100000 | P29: =N29*O29 -> 0 | X29: =W29*50000 -> 0 | Z29: =SUM(I29+P29+Q29+V29+X29+Y29+T29) -> 0
A30: 44946 | D30: =C30-B30 -> 0 | J30: 0 | K30: 0 | L30: =IF(("7:00"-J30)<=0,0,("7:00"-J30)) -> 0.29166667 | M30: =IF((K30-"18:00")<=0,0,(K30-"18:00")) -> 0 | N30: 0 | O30: 100000 | P30: =N30*O30 -> 0 | X30: =W30*50000 -> 0 | Z30: =SUM(I30+P30+Q30+V30+X30+Y30+T30) -> 0
A31: 44947 | D31: =C31-B31 -> 0 | J31: 0 | K31: 0 | L31: =IF(("7:00"-J31)<=0,0,("7:00"-J31)) -> 0.29166667 | M31: =IF((K31-"18:00")<=0,0,(K31-"18:00")) -> 0 | N31: 0 | O31: 100000 | P31: =N31*O31 -> 0 | X31: =W31*50000 -> 0 | Z31: =SUM(I31+P31+Q31+V31+X31+Y31+T31) -> 0
A32: 44948 | D32: =C32-B32 -> 0 | J32: 0 | K32: 0 | L32: =IF(("7:00"-J32)<=0,0,("7:00"-J32)) -> 0.29166667 | M32: =IF((K32-"18:00")<=0,0,(K32-"18:00")) -> 0 | N32: 0 | O32: 100000 | P32: =N32*O32 -> 0 | X32: =W32*50000 -> 0 | Z32: =SUM(I32+P32+Q32+V32+X32+Y32+T32) -> 0
A33: 44949 | D33: =C33-B33 -> 0 | J33: 0 | K33: 0 | L33: =IF(("7:00"-J33)<=0,0,("7:00"-J33)) -> 0.29166667 | M33: =IF((K33-"18:00")<=0,0,(K33-"18:00")) -> 0 | N33: 0 | O33: 100000 | P33: =N33*O33 -> 0 | X33: =W33*50000 -> 0 | Z33: =SUM(I33+P33+Q33+V33+X33+Y33+T33) -> 0
A34: 44950 | D34: =C34-B34 -> 0 | J34: 0 | K34: 0 | N34: 0 | O34: 100000 | P34: =N34*O34 -> 0 | X34: =W34*50000 -> 0 | Z34: =SUM(I34+P34+Q34+V34+X34+Y34+T34) -> 0
A35: 44951 | D35: =C35-B35 -> 0 | J35: 0 | K35: 0 | L35: =IF(("7:00"-J35)<=0,0,("7:00"-J35)) -> 0.29166667 | M35: =IF((K35-"18:00")<=0,0,(K35-"18:00")) -> 0 | N35: 0 | O35: 100000 | P35: =N35*O35 -> 0 | X35: =W35*50000 -> 0 | Z35: =SUM(I35+P35+Q35+V35+X35+Y35+T35) -> 0
A36: 44952 | D36: =C36-B36 -> 0 | J36: 0 | K36: 0 | N36: 0 | O36: 100000 | P36: =N36*O36 -> 0 | X36: =W36*50000 -> 0 | Z36: =SUM(I36+P36+Q36+V36+X36+Y36+T36) -> 0
A37: 44953 | D37: =C37-B37 -> 0 | J37: 0 | K37: 0 | L37: =IF(("7:00"-J37)<=0,0,("7:00"-J37)) -> 0.29166667 | M37: =IF((K37-"18:00")<=0,0,(K37-"18:00")) -> 0 | N37: 0 | O37: 100000 | P37: =N37*O37 -> 0 | X37: =W37*50000 -> 0 | Z37: =SUM(I37+P37+Q37+V37+X37+Y37+T37) -> 0
A38: 44954 | D38: =C38-B38 -> 0 | J38: 0 | K38: 0 | L38: =IF(("7:00"-J38)<=0,0,("7:00"-J38)) -> 0.29166667 | M38: =IF((K38-"18:00")<=0,0,(K38-"18:00")) -> 0 | N38: 0 | O38: 100000 | P38: =N38*O38 -> 0 | X38: =W38*50000 -> 0 | Z38: =SUM(I38+P38+Q38+V38+X38+Y38+T38) -> 0
A39: 44955 | B39: 83762 | C39: 83891 | D39: =C39-B39 -> 129 | J39: 0.375 | K39: 0.5 | L39: =IF(("7:00"-J39)<=0,0,("7:00"-J39)) -> 0 | M39: =IF((K39-"18:00")<=0,0,(K39-"18:00")) -> 0 | N39: 0 | O39: 100000 | P39: =N39*O39 -> 0 | R39: 3 | S39: =1000000/8 -> 125000 | T39: =R39*S39 -> 375000 | X39: =W39*50000 -> 0 | Y39: 20000 | Z39: =SUM(I39+P39+Q39+V39+X39+Y39+T39) -> 395000 | AA39: ĐÓN CAI ZONG SANG VIỆT NAM( SÂN BAY-KÝ TÚC)
A40: 44956 | B40: 83925 | C40: 84041 | D40: =C40-B40 -> 116 | J40: 0.3125 | K40: 0.89583333 | L40: =IF(("7:00"-J40)<=0,0,("7:00"-J40)) -> 0 | M40: =IF((K40-"18:00")<=0,0,(K40-"18:00")) -> 0.14583333 | N40: 1 | O40: 100000 | P40: =N40*O40 -> 100000 | X40: =W40*50000 -> 0 | Z40: =SUM(I40+P40+Q40+V40+X40+Y40+T40) -> 100000
...

Sheet BẢNG KÊ CHI TIẾT XE TDP THEM XE
A1: CÔNG TY TNHH 98 AN PHÁT | P1: Cộng Hòa Xã Hội Chủ Nghĩa Việt Nam
A2: ĐC: Thôn Đức Liễn – Xã Hồng Thái – Huyện Việt Yên – Tỉnh Bắc Giang–Việt Nam. | P2: Độc Lập - Tự Do - Hạnh Phúc
A3: BẢNG ĐỐI CHIẾU KHỐI LƯỢNG VÀ GIÁ TRỊ SỬ DỤNG XE Ô TÔ 租车使用对账明细表
A4: Tháng 08 năm 2023 2023年8月
A5: Loại xe: 07 chỗ ngồi- BKS: 98A36900
A6: Khách hàng客户: CÔNG TY TNHH CÔNG NGHIỆP NIENYI VIỆT NAM
V7: ĐVT: VND
A8: NGÀY 日期 | B8: Km đầu 开始公里 | C8: Km cuối 结束公里 | D8: SỐ KM 使用公里数 | E8: SỐ KM TRỌN GÓI THEO HỢP ĐỒNG 按合同的公里数 | G8: KM PHỤ TRỘI NGÀY THƯỜNG 平日超过公里数 | J8: Giờ B.Đầu 开始时间 | K8: Giờ K.Thúc 结束时间 | L8: Số giờ tăng ca | N8: GIỜ PHỤ TRỘI NGÀY THƯỜNG 平日超过时间 | Q8: ĐƠN GIÁ NGÀY QUA ĐÊM 过夜单价 | R8: ĐƠN GIÁ NGÀY CN/LỄ 礼拜天或节日的单价 | U8: GIỜ PHỤ TRỘI NGÀY CHỦ NHẬT/LỄ 礼拜天或节日超过时间 | W8: TIỀN ĂN 餐费 | Y8: TIỀN VÉ XE 过路费、车票 | Z8: CỘNG 合计
E9: SỐ KM 公里数 | F9: GIÁ TRỊ 金额 | G9: SỐ KM PHỤ TRỘI 超过公里数 | H9: ĐƠN GIÁ 单价 | I9: THÀNH TIỀN 金额 | N9: GIỜ 工时 | O9: ĐƠN GIÁ 单价 | P9: THÀNH TIÊN 金额 | R9: GIỜ 工时 | S9: ĐƠN GIÁ 单价 | T9: THÀNH TIỀN 金额 | U9: ĐƠN GIÁ 单价 | V9: THÀNH TIỀN 金额 | W9: SỐ BỮA ĂN 餐数量 | X9: THÀNH TIỀN 金额
E10: 3000 | F10: 25000000 | G10: =+D42-E10 -> 4291 | H10: 6500 | I10: =G10*H10 -> 27891500 | Z10: =F10+I10+P10+Q10+S10+V10+X10+Y10 -> 52891500
A11: 45139 | B11: 128902 | C11: 129242 | D11: =C11-B11 -> 340 | J11: 0.29166667 | K11: 0 | L11: 2 | N11: 1 | O11: =100000+100000 -> 200000 | P11: =N11*O11 -> 200000 | W11: 1 | X11: =W11*50000 -> 50000 | Y11: 70000 | Z11: =SUM(I11+P11+Q11+V11+X11+Y11+T11) -> 320000
A12: 45140 | B12: 129246 | C12: 129428 | D12: =C12-B12 -> 182 | J12: 0.29166667 | K12: 0.83333333 | N12: 1 | O12: 100000 | P12: =N12*O12 -> 100000 | X12: =W12*50000 -> 0 | Y12: 30000 | Z12: =SUM(I12+P12+Q12+V12+X12+Y12+T12) -> 130000
A13: 45141 | B13: 129432 | C13: 129616 | D13: =C13-B13 -> 184 | J13: 0.29166667 | K13: 0.83333333 | N13: 1 | O13: 100000 | P13: =N13*O13 -> 100000 | X13: =W13*50000 -> 0 | Z13: =SUM(I13+P13+Q13+V13+X13+Y13+T13) -> 100000
A14: 45142 | B14: 129622 | C14: 129773 | D14: =C14-B14 -> 151 | J14: 0.29166667 | K14: 0.85416667 | N14: 1 | O14: 100000 | P14: =N14*O14 -> 100000 | X14: =W14*50000 -> 0 | Z14: =SUM(I14+P14+Q14+V14+X14+Y14+T14) -> 100000
A15: 45143 | B15: 129781 | C15: 130141 | D15: =C15-B15 -> 360 | J15: 0.22916667 | K15: 0.66666667 | L15: 1.5 | O15: 75000 | P15: =O15 -> 75000 | X15: =W15*50000 -> 0 | Y15: 18000 | Z15: =SUM(I15+P15+Q15+V15+X15+Y15+T15) -> 93000
A16: 45144 | D16: =C16-B16 -> 0 | O16: 100000 | P16: =N16*O16 -> 0 | X16: =W16*50000 -> 0 | Z16: =SUM(I16+P16+Q16+V16+X16+Y16+T16) -> 0
A17: 45145 | B17: 130148 | C17: 130349 | D17: =C17-B17 -> 201 | J17: 0.29166667 | K17: 0.89583333 | N17: 1 | O17: 100000 | P17: =N17*O17 -> 100000 | X17: =W17*50000 -> 0 | Z17: =SUM(I17+P17+Q17+V17+X17+Y17+T17) -> 100000
A18: 45146 | B18: 130354 | C18: 130638 | D18: =C18-B18 -> 284 | J18: 0.29166667 | K18: 0.85416667 | N18: 1 | O18: 100000 | P18: =N18*O18 -> 100000 | X18: =W18*50000 -> 0 | Y18: =70000+50000 -> 120000 | Z18: =SUM(I18+P18+Q18+V18+X18+Y18+T18) -> 220000
A19: 45147 | B19: 130642 | C19: 130737 | D19: =C19-B19 -> 95 | J19: 0.29166667 | K19: 0.83333333 | N19: 1 | O19: 100000 | P19: =N19*O19 -> 100000 | X19: =W19*50000 -> 0 | Z19: =SUM(I19+P19+Q19+V19+X19+Y19+T19) -> 100000 | AA19: 1
A20: 45148 | B20: 130741 | C20: 130875 | D20: =C20-B20 -> 134 | J20: 0.29166667 | K20: 0.85416667 | N20: 1 | O20: 100000 | P20: =N20*O20 -> 100000 | X20: =W20*50000 -> 0 | Z20: =SUM(I20+P20+Q20+V20+X20+Y20+T20) -> 100000
A21: 45149 | B21: 130879 | C21: 130951 | D21: =C21-B21 -> 72 | J21: 0.29166667 | K21: 0.85416667 | N21: 1 | O21: 100000 | P21: =N21*O21 -> 100000 | X21: =W21*50000 -> 0 | Z21: =SUM(I21+P21+Q21+V21+X21+Y21+T21) -> 100000
A22: 45150 | B22: 130956 | C22: 131170 | D22: =C22-B22 -> 214 | J22: 0.20833333 | K22: 0.79166667 | L22: 2 | N22: 1 | O22: =100000+100000 -> 200000 | P22: =N22*O22 -> 200000 | X22: =W22*50000 -> 0 | Y22: 9000 | Z22: =SUM(I22+P22+Q22+V22+X22+Y22+T22) -> 209000 | AC22: từ 7h30 đến 18h là 10.5 tiếng, anh ngọc đi 9h đến 18h là 8 tiếng
A23: 45151 | B23: 131178 | C23: 131336 | D23: =C23-B23 -> 158 | J23: 0.64583333 | K23: 0.77083333 | L23: 0.5 | O23: =0.5*50000 -> 25000 | P23: 25000 | R23: 2.5 | S23: =1000000/8 -> 125000 | T23: =R23*S23 -> 312500 | X23: =W23*50000 -> 0 | Y23: 13000 | Z23: =SUM(I23+P23+Q23+V23+X23+Y23+T23) -> 350500
A24: 45152 | B24: 131340 | C24: 131579 | D24: =C24-B24 -> 239 | J24: 0.29166667 | K24: 0.85416667 | N24: 1 | O24: 100000 | P24: =N24*O24 -> 100000 | X24: =W24*50000 -> 0 | Z24: =SUM(I24+P24+Q24+V24+X24+Y24+T24) -> 100000
A25: 45153 | B25: 131583 | C25: 131841 | D25: =C25-B25 -> 258 | J25: 0.29166667 | K25: 0.85416667 | N25: 1 | O25: 100000 | P25: =N25*O25 -> 100000 | W25: 1 | X25: =W25*50000 -> 50000 | Z25: =SUM(I25+P25+Q25+V25+X25+Y25+T25) -> 150000
A26: 45154 | B26: 131846 | C26: 132011 | D26: =C26-B26 -> 165 | J26: 0.29166667 | K26: 0.83333333 | N26: 1 | O26: 100000 | P26: =N26*O26 -> 100000 | W26: 1 | X26: =W26*50000 -> 50000 | Z26: =SUM(I26+P26+Q26+V26+X26+Y26+T26) -> 150000
A27: 45155 | B27: 132015 | C27: 132227 | D27: =C27-B27 -> 212 | J27: 0.29166667 | K27: 0.89583333 | N27: 1 | O27: 100000 | P27: =N27*O27 -> 100000 | W27: 1 | X27: =W27*50000 -> 50000 | Z27: =SUM(I27+P27+Q27+V27+X27+Y27+T27) -> 150000
A28: 45156 | B28: 132234 | C28: 132503 | D28: =C28-B28 -> 269 | J28: 0.29166667 | K28: 0 | L28: 2 | N28: 1 | O28: =100000+100000 -> 200000 | P28: =N28*O28 -> 200000 | W28: 1 | X28: =W28*50000 -> 50000 | Z28: =SUM(I28+P28+Q28+V28+X28+Y28+T28) -> 250000
A29: 45157 | B29: 132508 | C29: 132871 | D29: =C29-B29 -> 363 | J29: 0.29166667 | K29: 0.125 | L29: 2 | N29: 1 | O29: =100000+100000 -> 200000 | P29: =N29*O29 -> 200000 | Q29: 300000 | X29: =W29*50000 -> 0 | Z29: =SUM(I29+P29+Q29+V29+X29+Y29+T29) -> 500000
A30: 45158 | D30: =C30-B30 -> 0 | O30: 100000 | P30: =N30*O30 -> 0 | X30: =W30*50000 -> 0 | Z30: =SUM(I30+P30+Q30+V30+X30+Y30+T30) -> 0
A31: 45159 | B31: 132886 | C31: 133141 | D31: =C31-B31 -> 255 | J31: 0.29166667 | K31: 0.85416667 | N31: 1 | O31: 100000 | P31: =N31*O31 -> 100000 | X31: =W31*50000 -> 0 | Z31: =SUM(I31+P31+Q31+V31+X31+Y31+T31) -> 100000
A32: 45160 | B32: 133146 | C32: 133276 | D32: =C32-B32 -> 130 | J32: 0.29166667 | K32: 0.85416667 | N32: 1 | O32: 100000 | P32: =N32*O32 -> 100000 | X32: =W32*50000 -> 0 | Z32: =SUM(I32+P32+Q32+V32+X32+Y32+T32) -> 100000
A33: 45161 | B33: 133280 | C33: 133497 | D33: =C33-B33 -> 217 | J33: 0.29166667 | K33: 0.85416667 | N33: 1 | O33: 100000 | P33: =N33*O33 -> 100000 | X33: =W33*50000 -> 0 | Z33: =SUM(I33+P33+Q33+V33+X33+Y33+T33) -> 100000
A34: 45162 | B34: 133502 | C34: 133900 | D34: =C34-B34 -> 398 | J34: 0.25 | K34: 0.95833333 | L34: =1+1 -> 2 | N34: 1 | O34: =100000+100000 -> 200000 | P34: =N34*O34 -> 200000 | W34: 2 | X34: =W34*50000 -> 100000 | Y34: =70000+9000 -> 79000 | Z34: =SUM(I34+P34+Q34+V34+X34+Y34+T34) -> 379000
A35: 45163 | B35: 133904 | C35: 134252 | D35: =C35-B35 -> 348 | J35: 0.29166667 | K35: 0.95833333 | L35: 1 | N35: 1 | O35: =50000+100000 -> 150000 | P35: =N35*O35 -> 150000 | W35: 1 | X35: =W35*50000 -> 50000 | Y35: =70000+50000+13000 -> 133000 | Z35: =SUM(I35+P35+Q35+V35+X35+Y35+T35) -> 333000
A36: 45164 | B36: 134259 | C36: 134493 | D36: =C36-B36 -> 234 | J36: 0.25 | K36: 0.8125 | L36: 1 | N36: 1 | O36: =50000+100000 -> 150000 | P36: =N36*O36 -> 150000 | X36: =W36*50000 -> 0 | Y36: 9000 | Z36: =SUM(I36+P36+Q36+V36+X36+Y36+T36) -> 159000
A37: 45165 | D37: =C37-B37 -> 0 | O37: 100000 | P37: =N37*O37 -> 0 | X37: =W37*50000 -> 0 | Z37: =SUM(I37+P37+Q37+V37+X37+Y37+T37) -> 0
A38: 45166 | B38: 134502 | C38: 134923 | D38: =C38-B38 -> 421 | J38: 0.29166667 | K38: 0.83333333 | N38: 1 | O38: 100000 | P38: =N38*O38 -> 100000 | W38: 1 | X38: =W38*50000 -> 50000 | Y38: 490000 | Z38: =SUM(I38+P38+Q38+V38+X38+Y38+T38) -> 640000
A39: 45167 | B39: 134928 | C39: 135198 | D39: =C39-B39 -> 270 | J39: 0.29166667 | K39: 0.85416667 | N39: 1 | O39: 100000 | P39: =N39*O39 -> 100000 | X39: =W39*50000 -> 0 | Z39: =SUM(I39+P39+Q39+V39+X39+Y39+T39) -> 100000
A40: 45168 | B40: 135202 | C40: 135367 | D40: =C40-B40 -> 165 | J40: 0.29166667 | K40: 0.85416667 | N40: 1 | O40: 100000 | P40: =N40*O40 -> 100000 | X40: =W40*50000 -> 0 | Z40: =SUM(I40+P40+Q40+V40+X40+Y40+T40) -> 100000
...

Sheet BẢNG KÊ CHI TIẾT XUẤT VAT 07
A1: CÔNG TY TNHH KINH DOANH DỊCH VỤ VẬN TẢI ĐỨC ANH | Q1: Cộng Hòa Xã Hội Chủ Nghĩa Việt Nam
A2: ĐC: Số 7, Tổ dân phố Hoàng Mai 1, Phường Nếnh, Tỉnh Bắc Ninh, Việt Nam. | Q2: Độc Lập - Tự Do - Hạnh Phúc
A3: BẢNG ĐỐI CHIẾU KHỐI LƯỢNG VÀ GIÁ TRỊ SỬ DỤNG XE Ô TÔ 租车使用对账明细表
A4: Tháng 07 năm 2026 2026 年07月
A5: Loại xe: tải HOWO SINOTRUK 8 TẤN- BKS: 99H10378
A6: Bảng kế số 072026-02 ngày 25/07/2026 kèm hóa đơn số: kí hiệu:
A7: Khách hàng客户: CÔNG TY TNHH CÔNG NGHIỆP NIENYI VIỆT NAM
X8: ĐVT: VND
A9: NGÀY 日期 | B9: Km đầu 开始公里 | C9: Km cuối 结束公里 | D9: SỐ KM 使用公里数 | E9: SỐ KM TRỌN GÓI THEO HỢP ĐỒNG 按合同的公里数 | G9: KM PHỤ TRỘI NGÀY THƯỜNG 平日超过公里数 | K9: Giờ B.Đầu 开始时间 | L9: Giờ K.Thúc 结束时间 | M9: Số giờ tăng ca 时间加班 | N9: THÀNH TIỀN tăng ca 金额加班 | O9: GIỜ PHỤ TRỘI NGÀY THƯỜNG 平日超过时间 | R9: ĐƠN GIÁ NGÀY QUA ĐÊM 过夜单价 | S9: ĐƠN GIÁ NGÀY CN/LỄ 礼拜天或节日的单价 | V9: GIỜ PHỤ TRỘI NGÀY CHỦ NHẬT/LỄ 礼拜天或节日超过时间 | Y9: TIỀN ĂN 餐费 | AA9: TIỀN VÉ XE 过路费、车票 | AB9: CỘNG 合计
E10: SỐ KM 公里数 | F10: GIÁ TRỊ 金额 | G10: SỐ KM PHỤ TRỘI 超过公里数 | H10: ĐƠN GIÁ 单价 | I10: THÀNH TIỀN 金额 | O10: GIỜ 工时 | P10: ĐƠN GIÁ 单价 | Q10: THÀNH TIÊN 金额 | S10: GIỜ 工时 | T10: ĐƠN GIÁ 单价 | U10: THÀNH TIỀN 金额 | V10: GIỜ 工时 | W10: ĐƠN GIÁ 单价 | X10: THÀNH TIỀN 金额 | Y10: SỐ BỮA ĂN 餐数量 | Z10: THÀNH TIỀN 金额
E11: 3000 | F11: 42000000 | G11: 0 | H11: 10000 | I11: =G11*H11 -> 0 | AB11: =F11+I11+Q11+R11+T11+X11+Z11+AA11 -> 42000000
A12: 46199 | B12: 2509 | C12: 2580 | D12: =+C12-B12 -> 71 | K12: 0.33333333 | L12: 0.75 | O12: 0 | P12: 0 | Q12: =O12*P12 -> 0 | AB12: =SUM(I12+N12+Q12+R12+X12+Z12+AA12+U12) -> 0
A13: 46200 | B13: 2580 | C13: 2641 | D13: =+C13-B13 -> 61 | K13: 0.33333333 | L13: 0.75 | O13: 0 | P13: 0 | Q13: =O13*P13 -> 0 | AB13: =SUM(I13+N13+Q13+R13+X13+Z13+AA13+U13) -> 0
A14: 46201 | B14: 0 | C14: 0 | D14: =+C14-B14 -> 0 | K14: 0 | L14: 0 | O14: 0 | P14: 0 | Q14: =O14*P14 -> 0 | AB14: =SUM(I14+N14+Q14+R14+X14+Z14+AA14+U14) -> 0
A15: 46202 | B15: 2641 | C15: 2704 | D15: =+C15-B15 -> 63 | K15: 0.33333333 | L15: 0.91666667 | O15: 4 | P15: 50000 | Q15: =O15*P15 -> 200000 | Y15: 2 | Z15: 100000 | AB15: =SUM(I15+N15+Q15+R15+X15+Z15+AA15+U15) -> 300000
A16: 46203 | B16: 2704 | C16: 2723 | D16: =+C16-B16 -> 19 | K16: 0.33333333 | L16: 0.79166667 | O16: 1 | P16: 50000 | Q16: =O16*P16 -> 50000 | AB16: =SUM(I16+N16+Q16+R16+X16+Z16+AA16+U16) -> 50000
A17: 46204 | B17: 2723 | C17: 2729 | D17: =+C17-B17 -> 6 | K17: 0.33333333 | L17: 0.75 | O17: 0 | P17: 0 | Q17: =O17*P17 -> 0 | AB17: =SUM(I17+N17+Q17+R17+X17+Z17+AA17+U17) -> 0
A18: 46205 | B18: 2729 | C18: 2786 | D18: =+C18-B18 -> 57 | K18: 0.33333333 | L18: 0.75 | O18: 0 | P18: 0 | Q18: =O18*P18 -> 0 | AB18: =SUM(I18+N18+Q18+R18+X18+Z18+AA18+U18) -> 0
A19: 46206 | B19: 2786 | C19: 2811 | D19: =+C19-B19 -> 25 | K19: 0.33333333 | L19: 0.75 | O19: 0 | P19: 0 | Q19: =O19*P19 -> 0 | AB19: =SUM(I19+N19+Q19+R19+X19+Z19+AA19+U19) -> 0
A20: 46207 | B20: 2811 | C20: 2831 | D20: =+C20-B20 -> 20 | K20: 0.33333333 | L20: 0.75 | O20: 0 | P20: 0 | Q20: =O20*P20 -> 0 | AB20: =SUM(I20+N20+Q20+R20+X20+Z20+AA20+U20) -> 0
A21: 46208 | B21: 0 | C21: 0 | D21: =+C21-B21 -> 0 | K21: 0 | L21: 0 | O21: 0 | P21: 0 | Q21: =O21*P21 -> 0 | AB21: =SUM(I21+N21+Q21+R21+X21+Z21+AA21+U21) -> 0 | AE21: từ 7h30 đến 18h là 10.5 tiếng, anh ngọc đi 9h đến 18h là 8 tiếng
A22: 46209 | B22: 2831 | C22: 2913 | D22: =+C22-B22 -> 82 | K22: 0.33333333 | L22: 0.75 | O22: 0 | P22: 0 | Q22: =O22*P22 -> 0 | Y22: 1 | Z22: 50000 | AB22: =SUM(I22+N22+Q22+R22+X22+Z22+AA22+U22) -> 50000
A23: 46210 | B23: 2913 | C23: 2931 | D23: =+C23-B23 -> 18 | K23: 0.33333333 | L23: 0.75 | O23: 0 | P23: 0 | Q23: =O23*P23 -> 0 | AB23: =SUM(I23+N23+Q23+R23+X23+Z23+AA23+U23) -> 0
A24: 46211 | B24: 2931 | C24: 2999 | D24: =+C24-B24 -> 68 | K24: 0.33333333 | L24: 0.95833333 | O24: 5 | P24: 50000 | Q24: =O24*P24 -> 250000 | Y24: 1 | Z24: 50000 | AB24: =SUM(I24+N24+Q24+R24+X24+Z24+AA24+U24) -> 300000
A25: 46212 | B25: 2999 | C25: 3076 | D25: =+C25-B25 -> 77 | K25: 0.33333333 | L25: 0.75 | O25: 0 | P25: 0 | Q25: =O25*P25 -> 0 | AB25: =SUM(I25+N25+Q25+R25+X25+Z25+AA25+U25) -> 0
A26: 46213 | B26: 3076 | C26: 3100 | D26: =+C26-B26 -> 24 | K26: 0.33333333 | L26: 0.75 | O26: 0 | P26: 0 | Q26: 0 | Y26: 1 | Z26: 50000 | AB26: =SUM(I26+N26+Q26+R26+X26+Z26+AA26+U26) -> 50000
A27: 46214 | B27: 3100 | C27: 3108 | D27: =+C27-B27 -> 8 | K27: 0.33333333 | L27: 0.75 | O27: 0 | P27: 0 | Q27: 0 | AB27: =SUM(I27+N27+Q27+R27+X27+Z27+AA27+U27) -> 0
A28: 46215 | B28: 0 | C28: 0 | D28: =+C28-B28 -> 0 | K28: 0 | L28: 0 | O28: 0 | P28: 0 | Q28: 0 | U28: =S28*T28 -> 0 | AB28: =SUM(I28+N28+Q28+R28+X28+Z28+AA28+U28) -> 0
A29: 46216 | B29: 3108 | C29: 3253 | D29: =+C29-B29 -> 145 | K29: 0.33333333 | L29: 0.875 | O29: 3 | P29: 50000 | Q29: =O29*P29 -> 150000 | AB29: =SUM(I29+N29+Q29+R29+X29+Z29+AA29+U29) -> 150000
A30: 46217 | B30: 3253 | C30: 3324 | D30: =+C30-B30 -> 71 | K30: 0.33333333 | L30: 0.75 | O30: 0 | P30: 0 | Q30: 0 | AB30: =SUM(I30+N30+Q30+R30+X30+Z30+AA30+U30) -> 0
A31: 46218 | B31: 3324 | C31: 3330 | D31: =+C31-B31 -> 6 | K31: 0.33333333 | L31: 0.75 | O31: 0 | P31: 0 | Q31: =O31*P31 -> 0 | AB31: =SUM(I31+N31+Q31+R31+X31+Z31+AA31+U31) -> 0
A32: 46219 | B32: 3330 | C32: 3342 | D32: =+C32-B32 -> 12 | K32: 0.33333333 | L32: 0.75 | O32: 0 | P32: 0 | Q32: =O32*P32 -> 0 | AB32: =SUM(I32+N32+Q32+R32+X32+Z32+AA32+U32) -> 0
A33: 46220 | B33: 3342 | C33: 3369 | D33: =+C33-B33 -> 27 | K33: 0.33333333 | L33: 0.75 | O33: 0 | P33: 0 | Q33: 0 | Y33: 1 | Z33: 50000 | AB33: =SUM(I33+N33+Q33+R33+X33+Z33+AA33+U33) -> 50000
A34: 46221 | B34: 3369 | C34: 3372 | D34: =+C34-B34 -> 3 | K34: 0.33333333 | L34: 0.75 | O34: 0 | P34: 0 | Q34: =O34*P34 -> 0 | U34: =S34*T34 -> 0 | AB34: =SUM(I34+N34+Q34+R34+X34+Z34+AA34+U34) -> 0
A35: 46222 | B35: 0 | C35: 0 | D35: =+C35-B35 -> 0 | K35: 0 | L35: 0 | O35: 0 | P35: 0 | Q35: =O35*P35 -> 0 | AB35: =SUM(I35+N35+Q35+R35+X35+Z35+AA35+U35) -> 0
A36: 46223 | B36: 3372 | C36: 3445 | D36: =+C36-B36 -> 73 | K36: 0.33333333 | L36: 0.75 | O36: 0 | P36: 0 | Q36: =O36*P36 -> 0 | Y36: 1 | Z36: 50000 | AB36: =SUM(I36+N36+Q36+R36+X36+Z36+AA36+U36) -> 50000
A37: 46224 | B37: 3445 | C37: 3469 | D37: =+C37-B37 -> 24 | K37: 0.33333333 | L37: 0.75 | O37: 0 | P37: 0 | Q37: =O37*P37 -> 0 | AB37: =SUM(I37+N37+Q37+R37+X37+Z37+AA37+U37) -> 0
A38: 46225 | B38: 3469 | C38: 3533 | D38: =+C38-B38 -> 64 | K38: 0.33333333 | L38: 0.75 | O38: 0 | P38: 0 | Q38: =O38*P38 -> 0 | Y38: 1 | Z38: 50000 | AB38: =SUM(I38+N38+Q38+R38+X38+Z38+AA38+U38) -> 50000
A39: 46226 | B39: 3533 | C39: 3543 | D39: =+C39-B39 -> 10 | K39: 0.33333333 | L39: 0.79166667 | O39: 1 | P39: 50000 | Q39: =O39*P39 -> 50000 | AB39: =SUM(I39+N39+Q39+R39+X39+Z39+AA39+U39) -> 50000
A40: 46227 | B40: 3543 | C40: 3567 | D40: =+C40-B40 -> 24 | K40: 0.33333333 | L40: 0.79166667 | O40: 1 | P40: 50000 | Q40: =O40*P40 -> 50000 | Y40: 1 | Z40: 50000 | AB40: =SUM(I40+N40+Q40+R40+X40+Z40+AA40+U40) -> 100000
...
